Workbook
Name JUROS: 'BASE SAC @amigodopairico'!$F$13:$F$374
Name SAC: 'BASE SAC @amigodopairico'!#REF!
Name SAC_Adiantamento: 'BASE SAC @amigodopairico'!$N$15:$N$434
Name SAC_Amortizacao: 'BASE SAC @amigodopairico'!$G$15:$G$434
Name SAC_AtualizacaoMonetaria: 'BASE SAC @amigodopairico'!$S$15:$S$434
Name SAC_Juros: 'BASE SAC @amigodopairico'!$F$15:$F$434
Name SAC_Parcela: 'BASE SAC @amigodopairico'!$L$15:$L$434
Name SAC_PrevisaoAtualizacaoMonetaria: 'BASE SAC @amigodopairico'!$S$15:$S$434
Name SAC_QuedaSaldoDevedor: 'BASE SAC @amigodopairico'!$J$15:$J$434
Name SAC_Trienio: 'BASE SAC @amigodopairico'!$A$15:$T$434
Name SALDO_DEVEDOR: 'BASE SAC @amigodopairico'!$M$13:$M$374

Sheet BASE SAC @amigodopairico
AD4: ONDE TE AJUDO MAIS ➡️ amigodopairico.com.br/paq
A5: =SUM(A15:A1187) -> 9725 | B5: =SUM(B15:B1187) -> 29175 | D5: SAC | F5: =SUM(F15:F1187) -> 814601.51 | G5: =SUM(G15:G1187) -> 561741.29 | L5: =SUM(L15:L1187) -> 1415242.8 | N5: =SUM(N15:N1187) -> 0 | S5: =SUM(S15:S1187) -> 165744.68 | AA5: =SUM(AA15:AA1187) -> -1415242.8 | AR5: =SUM(AR15:AR1187) -> 9725 | AS5: =SUM(AS15:AS1187) -> 29175 | AW5: =SUM(AW15:AW1187) -> 814601.51 | AX5: =SUM(AX15:AX1187) -> 561741.29 | AY5: SAC | BC5: =SUM(BC15:BC1187) -> 1415242.8 | BE5: =SUM(BE15:BE1187) -> 0 | BJ5: =SUM(BJ15:BJ1187) -> 165744.68
B6: DADOS | F6: SE NÃO FIZER NADA | M6: COM ESTRATÉGIA | AS6: DADOS | AW6: SE NÃO FIZER NADA | BD6: COM ESTRATÉGIA
C7: Taxa de juros | D7: 0.105 | E7: =((1+D7)^(1/12))-1 -> 0.0083551557 | G7: Meses | H7: 389 | M7: Passa a quitar em | N7: =IF(M434<G15,COUNTIF(L15:L434,">1"),"⚠️ MAIS DE 420") -> 389 | O7: =" "&TEXT(N7/12,"0,0") & " anos" -> 32,4 anos | X7: Nominal | Y7: 0.0766 | AA7: TIR | AD7: VERSÃO SAC ESSENCIAL DO SIMULADOR DE AMORTIZAÇÕES | AT7: Taxa de juros | AU7: =D7 -> 0.105 | AV7: =((1+AU7)^(1/12))-1 -> 0.0083551557 | AX7: Meses | AY7: =H7 -> 389 | BA7: 360 | BD7: Passa a quitar em | BE7: =IF(BD434<AX15,COUNTIF(BC15:BC434,">1"),"⚠️ MAIS DE 420") -> 389 | BF7: =" "&TEXT(BE7/12,"0,0") & " anos" -> 32,4 anos
C8: Valor financiado | D8: 396000 | G8: Correção monetária | H8: =S5 -> 165744.68 | J8: QUANTO É APROVEITADO | M8: Parcelas a menos | N8: =H7-N7 -> 0 | O8: =" "&TEXT(N8/12,"0,0") & " anos a menos" -> 0,0 anos a menos | U8: =IF(N8>0,N5/N8,0) -> 0 | V8: cada parcela | Y8: =Y7/12 -> 0.0063833333 | AA8: =(1+AA9)^12-1 -> 0.13146251 | AD8: DO AMIGO DO PAI RICO | AT8: Valor financiado | AU8: =D8 -> 396000 | AX8: Correção monetária | AY8: =BJ5 -> 165744.68 | BA8: =BG5 -> 0 | BD8: Parcelas a menos | BE8: =AY7-BE7 -> 0 | BF8: =" "&TEXT(BE8/12,"0,0") & " anos a menos" -> 0,0 anos a menos
C9: Correção Monetária | D9: 0.0017 | G9: Total inicial | H9: =BE10 -> 1415242.8 | J9: DO VALOR QUE VOCÊ PAGA | M9: Total pago | N9: =SUM(L15:L434)+SUM(N15:N434) -> 1415242.8 | X9: Efetiva | Y9: =(1+Y8)^12-1 -> 0.079347351 | AA9: =IRR(AA14:AA434) -> 0.010345739 | AT9: Correção Monetária | AU9: =D9 -> 0.0017 | AX9: Juros totais pagos | AY9: =CF9 -> 0 | BA9: =CH9 -> 0 | BD9: Juros pagos | BE9: =SUM(AW15:AW434)+AR5+AS5 -> 853501.51
C10: CET REAL | D10: =AA8 -> 0.13146251 | E10: =(1+D10)^(1/12)-1 -> 0.010345739 | G10: Juros + Seguro total | H10: =BE9 -> 853501.51 | J10: ⬇️ | M10: Juros pagos | N10: =SUM(F15:F434)+A5+B5 -> 853501.51 | AT10: CET REAL | AU10: =D10 -> 0.13146251 | AV10: =(1+AU10)^(1/12)-1 -> 0.010345739 | AX10: Total inicial | AY10: =CF10 -> 0 | BA10: =CH10 -> 0 | BD10: Total pago | BE10: =SUM(BC15:BC434)+SUM(BE15:BE434) -> 1415242.8
C11: Banco | D11: Caixa | M11: ECONOMIA TOTAL | N11: =H9-N9 -> 0 | AT11: Banco | AU11: =D11 -> Caixa | BD11: ECONOMIA TOTAL | BE11: =AY10-BE10 -> -1415242.8
A13: Taxa | B13: Seguro | C13: Momento | D13: % Amort Parcela | F13: Juros | G13: Amortização | J13: VALOR ÚTIL | K13: % VU | L13: Parcela do banco | M13: Saldo Devedor | N13: Amortização Ad | O13: T/V | P13: % $ | R13: Faltam | S13: At. Monetária | T13: AT. MONET. | AA13: FLUXO DE $ | AH13: Década | AI13: Triênio | AJ13: Ano | AK13: Dias | AR13: Taxa | AS13: Seguro | AT13: Momento | AU13: % Amort Parcela | AW13: Juros | AX13: Amortização | BA13: VALOR ÚTIL | BB13: % VU | BC13: Parcela do banco | BD13: Saldo Devedor | BE13: Amortização Ad | BF13: T/V | BG13: % $ | BI13: Faltam | BJ13: At. Monetária | BK13: AT. MONET.
C14: =DATE(YEAR(C15),MONTH(C15)-1,1) -> 46023 | AA14: =D8 -> 396000 | AK14: =DAY(DATE(YEAR(C14),MONTH(C14)+1,1)-1) -> 31 | AT14: =DATE(YEAR(AT15),MONTH(AT15)-1,1) -> 46023
A15: 25 | B15: 75 | C15: 46054 | D15: =IFERROR(G15/D8,0) -> 0.0025706941 | E15: 1 | F15: =IF(OR(D8<1,N14>D8),0,(D8-N14)*IF(D$11<>"BB",$E$7,(1+$D$7)^(AK14/365)-1)) -> 3308.6417 | G15: =IF(R15=0,0,IF(D8<1,0,(D8-N14)/R15)) -> 1017.9949 | H15: =IF(OR(G15=0,L15<1),"",IF(G15/L15>90%,"🛩",IF(G15/L15>70%,"🏎",IF(G15/L15>50%,"🚙",IF(G15/L15>30%,"🛵",IF(G15/L15>15%,"🐢","⚓️")))))) -> 🐢 | I15: =IFERROR(IF((G15+N15-S15)/L15<0,"🔙",IF((G15+N15-S15)/L15<10%,"🥾",IF((G15+N15-S15)/L15<20%,"🛴",IF((G15+N15-S15)/L15<50%,"🚴‍♂️",IF((G15+N15-S15)/L15<75%,"🚖","🚁"))))),"") -> 🥾 | J15: =G15+N15-S15 -> 344.79486 | K15: =IFERROR(J15/(L15+N15),0) -> 0.077890935 | L15: =G15+F15+A15+B15 -> 4426.6365 | M15: =IF(R15=0,0,MAX(0,D8-G15+S15-N14)) -> 395655.21 | O15: =IF(AND(N15<>"",N15<R15),"V","") | Q15: =IF(N15=0,"",IF(N15>M15,"🚫",IF(INT(N15/G15<1),"👍",INT(N15/G15)&"x"))) | R15: =H7 -> 389 | S15: =D8*$T15 -> 673.2 | T15: =D9 -> 0.0017 | AA15: =-(L15+N15) -> -4426.6365 | AH15: =ROUNDUP(E15/120,0) -> 1 | AI15: =ROUNDUP(E15/36,0) -> 1 | AJ15: =ROUNDUP(E15/12,0) -> 1 | AK15: =DAY(DATE(YEAR(C15),MONTH(C15)+1,1)-1) -> 28 | AR15: =A15 -> 25 | AS15: =B15 -> 75 | AT15: =C15 -> 46054 | AU15: =IFERROR(AX15/AU8,0) -> 0.0025706941 | AV15: 1 | AW15: =IF(OR(AU8<1,BE14>AU8),0,(AU8-BE14)*IF(AU$11<>"BB",$E$7,(1+$D$7)^(BY14/365)-1)) -> 3308.6417 | AX15: =IF(BI15=0,0,IF(AU8<1,0,(AU8-BE14)/BI15)) -> 1017.9949 | AY15: =IF(OR(AX15=0,BC15<1),"",IF(AX15/BC15>90%,"🛩",IF(AX15/BC15>70%,"🏎",IF(AX15/BC15>50%,"🚙",IF(AX15/BC15>30%,"🛵",IF(AX15/BC15>15%,"🐢","⚓️")))))) -> 🐢 | AZ15: =IFERROR(IF((AX15+BE15-BJ15)/BC15<0,"🔙",IF((AX15+BE15-BJ15)/BC15<10%,"🥾",IF((AX15+BE15-BJ15)/BC15<20%,"🛴",IF((AX15+BE15-BJ15)/BC15<50%,"🚴‍♂️",IF((AX15+BE15-BJ15)/BC15<75%,"🚖","🚁"))))),"") -> 🥾 | BA15: =AX15+BE15-BJ15 -> 344.79486 | BB15: =IFERROR(BA15/(BC15+BE15),0) -> 0.077890935 | BC15: =AX15+AW15+AR15+AS15 -> 4426.6365 | BD15: =IF(BI15=0,0,MAX(0,AU8-AX15+BJ15-BE14)) -> 395655.21 | BF15: =IF(AND(BE15<>"",BE15<BI15),"V","") | BH15: =IF(BE15=0,"",IF(BE15>BD15,"🚫",IF(INT(BE15/AX15<1),"👍",INT(BE15/AX15)&"x"))) | BI15: =AY7 -> 389 | BJ15: =AU8*$BK15 -> 673.2 | BK15: =AU9 -> 0.0017
A16: =IF(INT(F16)>0,A15,0) -> 25 | B16: =IF(F16>0.1,B15,0) -> 75 | C16: =DATE(YEAR(C15),MONTH(C15)+1,1) -> 46082 | D16: =IFERROR(G16/M15,0) -> 0.0025773196 | E16: =E15+1 -> 2 | F16: =IF(OR(M15<1,N15>M15),0,(M15-N15)*IF(D$11<>"BB",$E$7,(1+$D$7)^(AK15/365)-1)) -> 3305.7608 | G16: =IF(R16=0,0,IF(M15<1,0,IF(AND(((M15-N15)/R16)<G15,O15<>"V"),G15, (M15-N15)/R16))) -> 1019.7299 | H16: =IF(OR(G16=0,L16<1),"",IF(G16/L16>90%,"🛩",IF(G16/L16>70%,"🏎",IF(G16/L16>50%,"🚙",IF(G16/L16>30%,"🛵",IF(G16/L16>15%,"🐢","⚓️")))))) -> 🐢 | I16: =IFERROR(IF((G16+N16-S16)/L16<0,"🔙",IF((G16+N16-S16)/L16<10%,"🥾",IF((G16+N16-S16)/L16<20%,"🛴",IF((G16+N16-S16)/L16<50%,"🚴‍♂️",IF((G16+N16-S16)/L16<75%,"🚖","🚁"))))),"") -> 🥾 | J16: =G16+N16-S16 -> 347.11606 | K16: =IFERROR(J16/(L16+N16),0) -> 0.078435609 | L16: =G16+F16+A16+B16 -> 4425.4907 | M16: =IF(R16=0,0,MAX(0,M15-G16+S16-N15)) -> 395308.09 | O16: =IF(AND(N16<>"",N16<R16),"V","") | P16: =IF(N15=0,"",(L15-L16)/N15) | Q16: =IF(N16=0,"",IF(N16>M16,"🚫",IF(INT(N16/G16<1),"👍",INT(N16/G16)&"x"))) | R16: =IF(M15=0,0,IF(OR(N15=0,O15="V"),R15-1,IF(OR(D$11="BRADESCO",D$11="BB"),R15-ROUNDDOWN(N15/(M15/R15),0)-1,ROUNDUP((M15-N15+S15-(M15/R15))/(L15-F16-A16-B16),0)+1))) -> 388 | S16: =M15*$T16 -> 672.61385 | T16: =IF(M15>0,T15,0) -> 0.0017 | AA16: =-(L16+N16) -> -4425.4907 | AH16: =ROUNDUP(E16/120,0) -> 1 | AI16: =ROUNDUP(E16/36,0) -> 1 | AJ16: =ROUNDUP(E16/12,0) -> 1 | AK16: =DAY(DATE(YEAR(C16),MONTH(C16)+1,1)-1) -> 31 | AR16: =IF(INT(AW16)>0,AR15,0) -> 25 | AS16: =IF(AW16>0.1,AS15,0) -> 75 | AT16: =DATE(YEAR(AT15),MONTH(AT15)+1,1) -> 46082 | AU16: =IFERROR(AX16/BD15,0) -> 0.0025773196 | AV16: =AV15+1 -> 2 | AW16: =IF(OR(BD15<1,BE15>BD15),0,(BD15-BE15)*IF(AU$11<>"BB",$E$7,(1+$D$7)^(BY15/365)-1)) -> 3305.7608 | AX16: =IF(BI16=0,0,IF(BD15<1,0,IF(AND(((BD15-BE15)/BI16)<AX15,BF15<>"V"),AX15, (BD15-BE15)/BI16))) -> 1019.7299 | AY16: =IF(OR(AX16=0,BC16<1),"",IF(AX16/BC16>90%,"🛩",IF(AX16/BC16>70%,"🏎",IF(AX16/BC16>50%,"🚙",IF(AX16/BC16>30%,"🛵",IF(AX16/BC16>15%,"🐢","⚓️")))))) -> 🐢 | AZ16: =IFERROR(IF((AX16+BE16-BJ16)/BC16<0,"🔙",IF((AX16+BE16-BJ16)/BC16<10%,"🥾",IF((AX16+BE16-BJ16)/BC16<20%,"🛴",IF((AX16+BE16-BJ16)/BC16<50%,"🚴‍♂️",IF((AX16+BE16-BJ16)/BC16<75%,"🚖","🚁"))))),"") -> 🥾 | BA16: =AX16+BE16-BJ16 -> 347.11606 | BB16: =IFERROR(BA16/(BC16+BE16),0) -> 0.078435609 | BC16: =AX16+AW16+AR16+AS16 -> 4425.4907 | BD16: =IF(BI16=0,0,MAX(0,BD15-AX16+BJ16-BE15)) -> 395308.09 | BF16: =IF(AND(BE16<>"",BE16<BI16),"V","") | BG16: =IF(BE15=0,"",(BC15-BC16)/BE15) | BH16: =IF(BE16=0,"",IF(BE16>BD16,"🚫",IF(INT(BE16/AX16<1),"👍",INT(BE16/AX16)&"x"))) | BI16: =IF(BD15=0,0,IF(OR(BE15=0,BF15="V"),BI15-1,IF(OR(AU$11="BRADESCO",AU$11="BB"),BI15-ROUNDDOWN(BE15/(BD15/BI15),0)-1,ROUNDUP((BD15-BE15+BJ15-(BD15/BI15))/(BC15-AW16-AR16-AS16),0)+1))) -> 388 | BJ16: =BD15*$BK15 -> 672.61385 | BK16: =IF(BD15>0,BK15,0) -> 0.0017
A17: =IF(INT(F17)>0,A16,0) -> 25 | B17: =IF(F17>0.1,B16,0) -> 75 | C17: =DATE(YEAR(C16),MONTH(C16)+1,1) -> 46113 | D17: =IFERROR(G17/M16,0) -> 0.0025839793 | E17: =E16+1 -> 3 | F17: =IF(OR(M16<1,N16>M16),0,(M16-N16)*IF(D$11<>"BB",$E$7,(1+$D$7)^(AK16/365)-1)) -> 3302.8606 | G17: =IF(R17=0,0,IF(M16<1,0,IF(AND(AND(((M16-N16)/R17)<G16,O16<>"V"),D$11<>"BRADESCO"),G16, (M16-N16)/R17))) -> 1021.4679 | H17: =IF(OR(G17=0,L17<1),"",IF(G17/L17>90%,"🛩",IF(G17/L17>70%,"🏎",IF(G17/L17>50%,"🚙",IF(G17/L17>30%,"🛵",IF(G17/L17>15%,"🐢","⚓️")))))) -> 🐢 | I17: =IFERROR(IF((G17+N17-S17)/L17<0,"🔙",IF((G17+N17-S17)/L17<10%,"🥾",IF((G17+N17-S17)/L17<20%,"🛴",IF((G17+N17-S17)/L17<50%,"🚴‍♂️",IF((G17+N17-S17)/L17<75%,"🚖","🚁"))))),"") -> 🥾 | J17: =G17+N17-S17 -> 349.44418 | K17: =IFERROR(J17/(L17+N17),0) -> 0.078982421 | L17: =G17+F17+A17+B17 -> 4424.3286 | M17: =IF(R17=0,0,MAX(0,M16-G17+S17-N16)) -> 394958.64 | O17: =IF(AND(N17<>"",N17<R17),"V","") | P17: =IF(N16=0,"",(L16-L17)/N16) | Q17: =IF(N17=0,"",IF(N17>M17,"🚫",IF(INT(N17/G17<1),"👍",INT(N17/G17)&"x"))) | R17: =IF(M16=0,0,IF(OR(N16=0,O16="V"),R16-1,IF(OR(D$11="BRADESCO",D$11="BB"),R16-ROUNDDOWN(N16/(M16/R16),0)-1,ROUNDUP((M16-N16+S16-(M16/R16))/(L16-F17-A17-B17),0)+1))) -> 387 | S17: =M16*$T17 -> 672.02375 | T17: =IF(M16>0,T16,0) -> 0.0017 | AA17: =-(L17+N17) -> -4424.3286 | AH17: =ROUNDUP(E17/120,0) -> 1 | AI17: =ROUNDUP(E17/36,0) -> 1 | AJ17: =ROUNDUP(E17/12,0) -> 1 | AK17: =DAY(DATE(YEAR(C17),MONTH(C17)+1,1)-1) -> 30 | AR17: =IF(INT(AW17)>0,AR16,0) -> 25 | AS17: =IF(AW17>0.1,AS16,0) -> 75 | AT17: =DATE(YEAR(AT16),MONTH(AT16)+1,1) -> 46113 | AU17: =IFERROR(AX17/BD16,0) -> 0.0025839793 | AV17: =AV16+1 -> 3 | AW17: =IF(OR(BD16<1,BE16>BD16),0,(BD16-BE16)*IF(AU$11<>"BB",$E$7,(1+$D$7)^(BY16/365)-1)) -> 3302.8606 | AX17: =IF(BI17=0,0,IF(BD16<1,0,IF(AND(AND(((BD16-BE16)/BI17)<AX16,BF16<>"V"),AU$11<>"BRADESCO"),AX16, (BD16-BE16)/BI17))) -> 1021.4679 | AY17: =IF(OR(AX17=0,BC17<1),"",IF(AX17/BC17>90%,"🛩",IF(AX17/BC17>70%,"🏎",IF(AX17/BC17>50%,"🚙",IF(AX17/BC17>30%,"🛵",IF(AX17/BC17>15%,"🐢","⚓️")))))) -> 🐢 | AZ17: =IFERROR(IF((AX17+BE17-BJ17)/BC17<0,"🔙",IF((AX17+BE17-BJ17)/BC17<10%,"🥾",IF((AX17+BE17-BJ17)/BC17<20%,"🛴",IF((AX17+BE17-BJ17)/BC17<50%,"🚴‍♂️",IF((AX17+BE17-BJ17)/BC17<75%,"🚖","🚁"))))),"") -> 🥾 | BA17: =AX17+BE17-BJ17 -> 349.44418 | BB17: =IFERROR(BA17/(BC17+BE17),0) -> 0.078982421 | BC17: =AX17+AW17+AR17+AS17 -> 4424.3286 | BD17: =IF(BI17=0,0,MAX(0,BD16-AX17+BJ17-BE16)) -> 394958.64 | BF17: =IF(AND(BE17<>"",BE17<BI17),"V","") | BG17: =IF(BE16=0,"",(BC16-BC17)/BE16) | BH17: =IF(BE17=0,"",IF(BE17>BD17,"🚫",IF(INT(BE17/AX17<1),"👍",INT(BE17/AX17)&"x"))) | BI17: =IF(BD16=0,0,IF(OR(BE16=0,BF16="V"),BI16-1,IF(OR(AU$11="BRADESCO",AU$11="BB"),BI16-ROUNDDOWN(BE16/(BD16/BI16),0)-1,ROUNDUP((BD16-BE16+BJ16-(BD16/BI16))/(BC16-AW17-AR17-AS17),0)+1))) -> 387 | BJ17: =BD16*$BK16 -> 672.02375 | BK17: =IF(BD16>0,BK16,0) -> 0.0017
A18: =IF(INT(F18)>0,A17,0) -> 25 | B18: =IF(F18>0.1,B17,0) -> 75 | C18: =DATE(YEAR(C17),MONTH(C17)+1,1) -> 46143 | D18: =IFERROR(G18/M17,0) -> 0.0025906736 | E18: =E17+1 -> 4 | F18: =IF(OR(M17<1,N17>M17),0,(M17-N17)*IF(D$11<>"BB",$E$7,(1+$D$7)^(AK17/365)-1)) -> 3299.941 | G18: =IF(R18=0,0,IF(M17<1,0,IF(AND(AND(((M17-N17)/R18)<G17,O17<>"V"),D$11<>"BRADESCO"),G17, (M17-N17)/R18))) -> 1023.2089 | H18: =IF(OR(G18=0,L18<1),"",IF(G18/L18>90%,"🛩",IF(G18/L18>70%,"🏎",IF(G18/L18>50%,"🚙",IF(G18/L18>30%,"🛵",IF(G18/L18>15%,"🐢","⚓️")))))) -> 🐢 | I18: =IFERROR(IF((G18+N18-S18)/L18<0,"🔙",IF((G18+N18-S18)/L18<10%,"🥾",IF((G18+N18-S18)/L18<20%,"🛴",IF((G18+N18-S18)/L18<50%,"🚴‍♂️",IF((G18+N18-S18)/L18<75%,"🚖","🚁"))))),"") -> 🥾 | J18: =G18+N18-S18 -> 351.77923 | K18: =IFERROR(J18/(L18+N18),0) -> 0.079531383 | L18: =G18+F18+A18+B18 -> 4423.1499 | M18: =IF(R18=0,0,MAX(0,M17-G18+S18-N17)) -> 394606.87 | O18: =IF(AND(N18<>"",N18<R18),"V","") | P18: =IF(N17=0,"",(L17-L18)/N17) | Q18: =IF(N18=0,"",IF(N18>M18,"🚫",IF(INT(N18/G18<1),"👍",INT(N18/G18)&"x"))) | R18: =IF(M17=0,0,IF(OR(N17=0,O17="V"),R17-1,IF(OR(D$11="BRADESCO",D$11="BB"),R17-ROUNDDOWN(N17/(M17/R17),0)-1,ROUNDUP((M17-N17+S17-(M17/R17))/(L17-F18-A18-B18),0)+1))) -> 386 | S18: =M17*$T18 -> 671.4297 | T18: =IF(M17>0,T17,0) -> 0.0017 | AA18: =-(L18+N18) -> -4423.1499 | AH18: =ROUNDUP(E18/120,0) -> 1 | AI18: =ROUNDUP(E18/36,0) -> 1 | AJ18: =ROUNDUP(E18/12,0) -> 1 | AK18: =DAY(DATE(YEAR(C18),MONTH(C18)+1,1)-1) -> 31 | AR18: =IF(INT(AW18)>0,AR17,0) -> 25 | AS18: =IF(AW18>0.1,AS17,0) -> 75 | AT18: =DATE(YEAR(AT17),MONTH(AT17)+1,1) -> 46143 | AU18: =IFERROR(AX18/BD17,0) -> 0.0025906736 | AV18: =AV17+1 -> 4 | AW18: =IF(OR(BD17<1,BE17>BD17),0,(BD17-BE17)*IF(AU$11<>"BB",$E$7,(1+$D$7)^(BY17/365)-1)) -> 3299.941 | AX18: =IF(BI18=0,0,IF(BD17<1,0,IF(AND(AND(((BD17-BE17)/BI18)<AX17,BF17<>"V"),AU$11<>"BRADESCO"),AX17, (BD17-BE17)/BI18))) -> 1023.2089 | AY18: =IF(OR(AX18=0,BC18<1),"",IF(AX18/BC18>90%,"🛩",IF(AX18/BC18>70%,"🏎",IF(AX18/BC18>50%,"🚙",IF(AX18/BC18>30%,"🛵",IF(AX18/BC18>15%,"🐢","⚓️")))))) -> 🐢 | AZ18: =IFERROR(IF((AX18+BE18-BJ18)/BC18<0,"🔙",IF((AX18+BE18-BJ18)/BC18<10%,"🥾",IF((AX18+BE18-BJ18)/BC18<20%,"🛴",IF((AX18+BE18-BJ18)/BC18<50%,"🚴‍♂️",IF((AX18+BE18-BJ18)/BC18<75%,"🚖","🚁"))))),"") -> 🥾 | BA18: =AX18+BE18-BJ18 -> 351.77923 | BB18: =IFERROR(BA18/(BC18+BE18),0) -> 0.079531383 | BC18: =AX18+AW18+AR18+AS18 -> 4423.1499 | BD18: =IF(BI18=0,0,MAX(0,BD17-AX18+BJ18-BE17)) -> 394606.87 | BF18: =IF(AND(BE18<>"",BE18<BI18),"V","") | BG18: =IF(BE17=0,"",(BC17-BC18)/BE17) | BH18: =IF(BE18=0,"",IF(BE18>BD18,"🚫",IF(INT(BE18/AX18<1),"👍",INT(BE18/AX18)&"x"))) | BI18: =IF(BD17=0,0,IF(OR(BE17=0,BF17="V"),BI17-1,IF(OR(AU$11="BRADESCO",AU$11="BB"),BI17-ROUNDDOWN(BE17/(BD17/BI17),0)-1,ROUNDUP((BD17-BE17+BJ17-(BD17/BI17))/(BC17-AW18-AR18-AS18),0)+1))) -> 386 | BJ18: =BD17*$BK17 -> 671.4297 | BK18: =IF(BD17>0,BK17,0) -> 0.0017
A19: =IF(INT(F19)>0,A18,0) -> 25 | B19: =IF(F19>0.1,B18,0) -> 75 | C19: =DATE(YEAR(C18),MONTH(C18)+1,1) -> 46174 | D19: =IFERROR(G19/M18,0) -> 0.0025974026 | E19: =E18+1 -> 5 | F19: =IF(OR(M18<1,N18>M18),0,(M18-N18)*IF(D$11<>"BB",$E$7,(1+$D$7)^(AK18/365)-1)) -> 3297.0018 | G19: =IF(R19=0,0,IF(M18<1,0,IF(AND(AND(((M18-N18)/R19)<G18,O18<>"V"),D$11<>"BRADESCO"),G18, (M18-N18)/R19))) -> 1024.9529 | H19: =IF(OR(G19=0,L19<1),"",IF(G19/L19>90%,"🛩",IF(G19/L19>70%,"🏎",IF(G19/L19>50%,"🚙",IF(G19/L19>30%,"🛵",IF(G19/L19>15%,"🐢","⚓️")))))) -> 🐢 | I19: =IFERROR(IF((G19+N19-S19)/L19<0,"🔙",IF((G19+N19-S19)/L19<10%,"🥾",IF((G19+N19-S19)/L19<20%,"🛴",IF((G19+N19-S19)/L19<50%,"🚴‍♂️",IF((G19+N19-S19)/L19<75%,"🚖","🚁"))))),"") -> 🥾 | J19: =G19+N19-S19 -> 354.12123 | K19: =IFERROR(J19/(L19+N19),0) -> 0.080082509 | L19: =G19+F19+A19+B19 -> 4421.9547 | M19: =IF(R19=0,0,MAX(0,M18-G19+S19-N18)) -> 394252.74 | O19: =IF(AND(N19<>"",N19<R19),"V","") | P19: =IF(N18=0,"",(L18-L19)/N18) | Q19: =IF(N19=0,"",IF(N19>M19,"🚫",IF(INT(N19/G19<1),"👍",INT(N19/G19)&"x"))) | R19: =IF(M18=0,0,IF(OR(N18=0,O18="V"),R18-1,IF(OR(D$11="BRADESCO",D$11="BB"),R18-ROUNDDOWN(N18/(M18/R18),0)-1,ROUNDUP((M18-N18+S18-(M18/R18))/(L18-F19-A19-B19),0)+1))) -> 385 | S19: =M18*$T19 -> 670.83167 | T19: =IF(M18>0,T18,0) -> 0.0017 | AA19: =-(L19+N19) -> -4421.9547 | AH19: =ROUNDUP(E19/120,0) -> 1 | AI19: =ROUNDUP(E19/36,0) -> 1 | AJ19: =ROUNDUP(E19/12,0) -> 1 | AK19: =DAY(DATE(YEAR(C19),MONTH(C19)+1,1)-1) -> 30 | AR19: =IF(INT(AW19)>0,AR18,0) -> 25 | AS19: =IF(AW19>0.1,AS18,0) -> 75 | AT19: =DATE(YEAR(AT18),MONTH(AT18)+1,1) -> 46174 | AU19: =IFERROR(AX19/BD18,0) -> 0.0025974026 | AV19: =AV18+1 -> 5 | AW19: =IF(OR(BD18<1,BE18>BD18),0,(BD18-BE18)*IF(AU$11<>"BB",$E$7,(1+$D$7)^(BY18/365)-1)) -> 3297.0018 | AX19: =IF(BI19=0,0,IF(BD18<1,0,IF(AND(AND(((BD18-BE18)/BI19)<AX18,BF18<>"V"),AU$11<>"BRADESCO"),AX18, (BD18-BE18)/BI19))) -> 1024.9529 | AY19: =IF(OR(AX19=0,BC19<1),"",IF(AX19/BC19>90%,"🛩",IF(AX19/BC19>70%,"🏎",IF(AX19/BC19>50%,"🚙",IF(AX19/BC19>30%,"🛵",IF(AX19/BC19>15%,"🐢","⚓️")))))) -> 🐢 | AZ19: =IFERROR(IF((AX19+BE19-BJ19)/BC19<0,"🔙",IF((AX19+BE19-BJ19)/BC19<10%,"🥾",IF((AX19+BE19-BJ19)/BC19<20%,"🛴",IF((AX19+BE19-BJ19)/BC19<50%,"🚴‍♂️",IF((AX19+BE19-BJ19)/BC19<75%,"🚖","🚁"))))),"") -> 🥾 | BA19: =AX19+BE19-BJ19 -> 354.12123 | BB19: =IFERROR(BA19/(BC19+BE19),0) -> 0.080082509 | BC19: =AX19+AW19+AR19+AS19 -> 4421.9547 | BD19: =IF(BI19=0,0,MAX(0,BD18-AX19+BJ19-BE18)) -> 394252.74 | BF19: =IF(AND(BE19<>"",BE19<BI19),"V","") | BG19: =IF(BE18=0,"",(BC18-BC19)/BE18) | BH19: =IF(BE19=0,"",IF(BE19>BD19,"🚫",IF(INT(BE19/AX19<1),"👍",INT(BE19/AX19)&"x"))) | BI19: =IF(BD18=0,0,IF(OR(BE18=0,BF18="V"),BI18-1,IF(OR(AU$11="BRADESCO",AU$11="BB"),BI18-ROUNDDOWN(BE18/(BD18/BI18),0)-1,ROUNDUP((BD18-BE18+BJ18-(BD18/BI18))/(BC18-AW19-AR19-AS19),0)+1))) -> 385 | BJ19: =BD18*$BK18 -> 670.83167 | BK19: =IF(BD18>0,BK18,0) -> 0.0017
A20: =IF(INT(F20)>0,A19,0) -> 25 | B20: =IF(F20>0.1,B19,0) -> 75 | C20: =DATE(YEAR(C19),MONTH(C19)+1,1) -> 46204 | D20: =IFERROR(G20/M19,0) -> 0.0026041667 | E20: =E19+1 -> 6 | F20: =IF(OR(M19<1,N19>M19),0,(M19-N19)*IF(D$11<>"BB",$E$7,(1+$D$7)^(AK19/365)-1)) -> 3294.0431 | G20: =IF(R20=0,0,IF(M19<1,0,IF(AND(AND(((M19-N19)/R20)<G19,O19<>"V"),D$11<>"BRADESCO"),G19, (M19-N19)/R20))) -> 1026.6999 | H20: =IF(OR(G20=0,L20<1),"",IF(G20/L20>90%,"🛩",IF(G20/L20>70%,"🏎",IF(G20/L20>50%,"🚙",IF(G20/L20>30%,"🛵",IF(G20/L20>15%,"🐢","⚓️")))))) -> 🐢 | I20: =IFERROR(IF((G20+N20-S20)/L20<0,"🔙",IF((G20+N20-S20)/L20<10%,"🥾",IF((G20+N20-S20)/L20<20%,"🛴",IF((G20+N20-S20)/L20<50%,"🚴‍♂️",IF((G20+N20-S20)/L20<75%,"🚖","🚁"))))),"") -> 🥾 | J20: =G20+N20-S20 -> 356.47019 | K20: =IFERROR(J20/(L20+N20),0) -> 0.080635811 | L20: =G20+F20+A20+B20 -> 4420.7429 | M20: =IF(R20=0,0,MAX(0,M19-G20+S20-N19)) -> 393896.27 | O20: =IF(AND(N20<>"",N20<R20),"V","") | P20: =IF(N19=0,"",(L19-L20)/N19) | Q20: =IF(N20=0,"",IF(N20>M20,"🚫",IF(INT(N20/G20<1),"👍",INT(N20/G20)&"x"))) | R20: =IF(M19=0,0,IF(OR(N19=0,O19="V"),R19-1,IF(OR(D$11="BRADESCO",D$11="BB"),R19-ROUNDDOWN(N19/(M19/R19),0)-1,ROUNDUP((M19-N19+S19-(M19/R19))/(L19-F20-A20-B20),0)+1))) -> 384 | S20: =M19*$T20 -> 670.22967 | T20: =IF(M19>0,T19,0) -> 0.0017 | AA20: =-(L20+N20) -> -4420.7429 | AH20: =ROUNDUP(E20/120,0) -> 1 | AI20: =ROUNDUP(E20/36,0) -> 1 | AJ20: =ROUNDUP(E20/12,0) -> 1 | AK20: =DAY(DATE(YEAR(C20),MONTH(C20)+1,1)-1) -> 31 | AR20: =IF(INT(AW20)>0,AR19,0) -> 25 | AS20: =IF(AW20>0.1,AS19,0) -> 75 | AT20: =DATE(YEAR(AT19),MONTH(AT19)+1,1) -> 46204 | AU20: =IFERROR(AX20/BD19,0) -> 0.0026041667 | AV20: =AV19+1 -> 6 | AW20: =IF(OR(BD19<1,BE19>BD19),0,(BD19-BE19)*IF(AU$11<>"BB",$E$7,(1+$D$7)^(BY19/365)-1)) -> 3294.0431 | AX20: =IF(BI20=0,0,IF(BD19<1,0,IF(AND(AND(((BD19-BE19)/BI20)<AX19,BF19<>"V"),AU$11<>"BRADESCO"),AX19, (BD19-BE19)/BI20))) -> 1026.6999 | AY20: =IF(OR(AX20=0,BC20<1),"",IF(AX20/BC20>90%,"🛩",IF(AX20/BC20>70%,"🏎",IF(AX20/BC20>50%,"🚙",IF(AX20/BC20>30%,"🛵",IF(AX20/BC20>15%,"🐢","⚓️")))))) -> 🐢 | AZ20: =IFERROR(IF((AX20+BE20-BJ20)/BC20<0,"🔙",IF((AX20+BE20-BJ20)/BC20<10%,"🥾",IF((AX20+BE20-BJ20)/BC20<20%,"🛴",IF((AX20+BE20-BJ20)/BC20<50%,"🚴‍♂️",IF((AX20+BE20-BJ20)/BC20<75%,"🚖","🚁"))))),"") -> 🥾 | BA20: =AX20+BE20-BJ20 -> 356.47019 | BB20: =IFERROR(BA20/(BC20+BE20),0) -> 0.080635811 | BC20: =AX20+AW20+AR20+AS20 -> 4420.7429 | BD20: =IF(BI20=0,0,MAX(0,BD19-AX20+BJ20-BE19)) -> 393896.27 | BF20: =IF(AND(BE20<>"",BE20<BI20),"V","") | BG20: =IF(BE19=0,"",(BC19-BC20)/BE19) | BH20: =IF(BE20=0,"",IF(BE20>BD20,"🚫",IF(INT(BE20/AX20<1),"👍",INT(BE20/AX20)&"x"))) | BI20: =IF(BD19=0,0,IF(OR(BE19=0,BF19="V"),BI19-1,IF(OR(AU$11="BRADESCO",AU$11="BB"),BI19-ROUNDDOWN(BE19/(BD19/BI19),0)-1,ROUNDUP((BD19-BE19+BJ19-(BD19/BI19))/(BC19-AW20-AR20-AS20),0)+1))) -> 384 | BJ20: =BD19*$BK19 -> 670.22967 | BK20: =IF(BD19>0,BK19,0) -> 0.0017
A21: =IF(INT(F21)>0,A20,0) -> 25 | B21: =IF(F21>0.1,B20,0) -> 75 | C21: =DATE(YEAR(C20),MONTH(C20)+1,1) -> 46235 | D21: =IFERROR(G21/M20,0) -> 0.0026109661 | E21: =E20+1 -> 7 | F21: =IF(OR(M20<1,N20>M20),0,(M20-N20)*IF(D$11<>"BB",$E$7,(1+$D$7)^(AK20/365)-1)) -> 3291.0647 | G21: =IF(R21=0,0,IF(M20<1,0,IF(AND(AND(((M20-N20)/R21)<G20,O20<>"V"),D$11<>"BRADESCO"),G20, (M20-N20)/R21))) -> 1028.4498 | H21: =IF(OR(G21=0,L21<1),"",IF(G21/L21>90%,"🛩",IF(G21/L21>70%,"🏎",IF(G21/L21>50%,"🚙",IF(G21/L21>30%,"🛵",IF(G21/L21>15%,"🐢","⚓️")))))) -> 🐢 | I21: =IFERROR(IF((G21+N21-S21)/L21<0,"🔙",IF((G21+N21-S21)/L21<10%,"🥾",IF((G21+N21-S21)/L21<20%,"🛴",IF((G21+N21-S21)/L21<50%,"🚴‍♂️",IF((G21+N21-S21)/L21<75%,"🚖","🚁"))))),"") -> 🥾 | J21: =G21+N21-S21 -> 358.82614 | K21: =IFERROR(J21/(L21+N21),0) -> 0.081191302 | L21: =G21+F21+A21+B21 -> 4419.5145 | M21: =IF(R21=0,0,MAX(0,M20-G21+S21-N20)) -> 393537.45 | O21: =IF(AND(N21<>"",N21<R21),"V","") | P21: =IF(N20=0,"",(L20-L21)/N20) | Q21: =IF(N21=0,"",IF(N21>M21,"🚫",IF(INT(N21/G21<1),"👍",INT(N21/G21)&"x"))) | R21: =IF(M20=0,0,IF(OR(N20=0,O20="V"),R20-1,IF(OR(D$11="BRADESCO",D$11="BB"),R20-ROUNDDOWN(N20/(M20/R20),0)-1,ROUNDUP((M20-N20+S20-(M20/R20))/(L20-F21-A21-B21),0)+1))) -> 383 | S21: =M20*$T21 -> 669.62367 | T21: =IF(M20>0,T20,0) -> 0.0017 | AA21: =-(L21+N21) -> -4419.5145 | AH21: =ROUNDUP(E21/120,0) -> 1 | AI21: =ROUNDUP(E21/36,0) -> 1 | AJ21: =ROUNDUP(E21/12,0) -> 1 | AK21: =DAY(DATE(YEAR(C21),MONTH(C21)+1,1)-1) -> 31 | AR21: =IF(INT(AW21)>0,AR20,0) -> 25 | AS21: =IF(AW21>0.1,AS20,0) -> 75 | AT21: =DATE(YEAR(AT20),MONTH(AT20)+1,1) -> 46235 | AU21: =IFERROR(AX21/BD20,0) -> 0.0026109661 | AV21: =AV20+1 -> 7 | AW21: =IF(OR(BD20<1,BE20>BD20),0,(BD20-BE20)*IF(AU$11<>"BB",$E$7,(1+$D$7)^(BY20/365)-1)) -> 3291.0647 | AX21: =IF(BI21=0,0,IF(BD20<1,0,IF(AND(AND(((BD20-BE20)/BI21)<AX20,BF20<>"V"),AU$11<>"BRADESCO"),AX20, (BD20-BE20)/BI21))) -> 1028.4498 | AY21: =IF(OR(AX21=0,BC21<1),"",IF(AX21/BC21>90%,"🛩",IF(AX21/BC21>70%,"🏎",IF(AX21/BC21>50%,"🚙",IF(AX21/BC21>30%,"🛵",IF(AX21/BC21>15%,"🐢","⚓️")))))) -> 🐢 | AZ21: =IFERROR(IF((AX21+BE21-BJ21)/BC21<0,"🔙",IF((AX21+BE21-BJ21)/BC21<10%,"🥾",IF((AX21+BE21-BJ21)/BC21<20%,"🛴",IF((AX21+BE21-BJ21)/BC21<50%,"🚴‍♂️",IF((AX21+BE21-BJ21)/BC21<75%,"🚖","🚁"))))),"") -> 🥾 | BA21: =AX21+BE21-BJ21 -> 358.82614 | BB21: =IFERROR(BA21/(BC21+BE21),0) -> 0.081191302 | BC21: =AX21+AW21+AR21+AS21 -> 4419.5145 | BD21: =IF(BI21=0,0,MAX(0,BD20-AX21+BJ21-BE20)) -> 393537.45 | BF21: =IF(AND(BE21<>"",BE21<BI21),"V","") | BG21: =IF(BE20=0,"",(BC20-BC21)/BE20) | BH21: =IF(BE21=0,"",IF(BE21>BD21,"🚫",IF(INT(BE21/AX21<1),"👍",INT(BE21/AX21)&"x"))) | BI21: =IF(BD20=0,0,IF(OR(BE20=0,BF20="V"),BI20-1,IF(OR(AU$11="BRADESCO",AU$11="BB"),BI20-ROUNDDOWN(BE20/(BD20/BI20),0)-1,ROUNDUP((BD20-BE20+BJ20-(BD20/BI20))/(BC20-AW21-AR21-AS21),0)+1))) -> 383 | BJ21: =BD20*$BK20 -> 669.62367 | BK21: =IF(BD20>0,BK20,0) -> 0.0017
A22: =IF(INT(F22)>0,A21,0) -> 25 | B22: =IF(F22>0.1,B21,0) -> 75 | C22: =DATE(YEAR(C21),MONTH(C21)+1,1) -> 46266 | D22: =IFERROR(G22/M21,0) -> 0.002617801 | E22: =E21+1 -> 8 | F22: =IF(OR(M21<1,N21>M21),0,(M21-N21)*IF(D$11<>"BB",$E$7,(1+$D$7)^(AK21/365)-1)) -> 3288.0666 | G22: =IF(R22=0,0,IF(M21<1,0,IF(AND(AND(((M21-N21)/R22)<G21,O21<>"V"),D$11<>"BRADESCO"),G21, (M21-N21)/R22))) -> 1030.2027 | H22: =IF(OR(G22=0,L22<1),"",IF(G22/L22>90%,"🛩",IF(G22/L22>70%,"🏎",IF(G22/L22>50%,"🚙",IF(G22/L22>30%,"🛵",IF(G22/L22>15%,"🐢","⚓️")))))) -> 🐢 | I22: =IFERROR(IF((G22+N22-S22)/L22<0,"🔙",IF((G22+N22-S22)/L22<10%,"🥾",IF((G22+N22-S22)/L22<20%,"🛴",IF((G22+N22-S22)/L22<50%,"🚴‍♂️",IF((G22+N22-S22)/L22<75%,"🚖","🚁"))))),"") -> 🥾 | J22: =G22+N22-S22 -> 361.18908 | K22: =IFERROR(J22/(L22+N22),0) -> 0.081748995 | L22: =G22+F22+A22+B22 -> 4418.2694 | M22: =IF(R22=0,0,MAX(0,M21-G22+S22-N21)) -> 393176.26 | O22: =IF(AND(N22<>"",N22<R22),"V","") | P22: =IF(N21=0,"",(L21-L22)/N21) | Q22: =IF(N22=0,"",IF(N22>M22,"🚫",IF(INT(N22/G22<1),"👍",INT(N22/G22)&"x"))) | R22: =IF(M21=0,0,IF(OR(N21=0,O21="V"),R21-1,IF(OR(D$11="BRADESCO",D$11="BB"),R21-ROUNDDOWN(N21/(M21/R21),0)-1,ROUNDUP((M21-N21+S21-(M21/R21))/(L21-F22-A22-B22),0)+1))) -> 382 | S22: =M21*$T22 -> 669.01366 | T22: =IF(M21>0,T21,0) -> 0.0017 | AA22: =-(L22+N22) -> -4418.2694 | AH22: =ROUNDUP(E22/120,0) -> 1 | AI22: =ROUNDUP(E22/36,0) -> 1 | AJ22: =ROUNDUP(E22/12,0) -> 1 | AK22: =DAY(DATE(YEAR(C22),MONTH(C22)+1,1)-1) -> 30 | AR22: =IF(INT(AW22)>0,AR21,0) -> 25 | AS22: =IF(AW22>0.1,AS21,0) -> 75 | AT22: =DATE(YEAR(AT21),MONTH(AT21)+1,1) -> 46266 | AU22: =IFERROR(AX22/BD21,0) -> 0.002617801 | AV22: =AV21+1 -> 8 | AW22: =IF(OR(BD21<1,BE21>BD21),0,(BD21-BE21)*IF(AU$11<>"BB",$E$7,(1+$D$7)^(BY21/365)-1)) -> 3288.0666 | AX22: =IF(BI22=0,0,IF(BD21<1,0,IF(AND(AND(((BD21-BE21)/BI22)<AX21,BF21<>"V"),AU$11<>"BRADESCO"),AX21, (BD21-BE21)/BI22))) -> 1030.2027 | AY22: =IF(OR(AX22=0,BC22<1),"",IF(AX22/BC22>90%,"🛩",IF(AX22/BC22>70%,"🏎",IF(AX22/BC22>50%,"🚙",IF(AX22/BC22>30%,"🛵",IF(AX22/BC22>15%,"🐢","⚓️")))))) -> 🐢 | AZ22: =IFERROR(IF((AX22+BE22-BJ22)/BC22<0,"🔙",IF((AX22+BE22-BJ22)/BC22<10%,"🥾",IF((AX22+BE22-BJ22)/BC22<20%,"🛴",IF((AX22+BE22-BJ22)/BC22<50%,"🚴‍♂️",IF((AX22+BE22-BJ22)/BC22<75%,"🚖","🚁"))))),"") -> 🥾 | BA22: =AX22+BE22-BJ22 -> 361.18908 | BB22: =IFERROR(BA22/(BC22+BE22),0) -> 0.081748995 | BC22: =AX22+AW22+AR22+AS22 -> 4418.2694 | BD22: =IF(BI22=0,0,MAX(0,BD21-AX22+BJ22-BE21)) -> 393176.26 | BF22: =IF(AND(BE22<>"",BE22<BI22),"V","") | BG22: =IF(BE21=0,"",(BC21-BC22)/BE21) | BH22: =IF(BE22=0,"",IF(BE22>BD22,"🚫",IF(INT(BE22/AX22<1),"👍",INT(BE22/AX22)&"x"))) | BI22: =IF(BD21=0,0,IF(OR(BE21=0,BF21="V"),BI21-1,IF(OR(AU$11="BRADESCO",AU$11="BB"),BI21-ROUNDDOWN(BE21/(BD21/BI21),0)-1,ROUNDUP((BD21-BE21+BJ21-(BD21/BI21))/(BC21-AW22-AR22-AS22),0)+1))) -> 382 | BJ22: =BD21*$BK21 -> 669.01366 | BK22: =IF(BD21>0,BK21,0) -> 0.0017
A23: =IF(INT(F23)>0,A22,0) -> 25 | B23: =IF(F23>0.1,B22,0) -> 75 | C23: =DATE(YEAR(C22),MONTH(C22)+1,1) -> 46296 | D23: =IFERROR(G23/M22,0) -> 0.0026246719 | E23: =E22+1 -> 9 | F23: =IF(OR(M22<1,N22>M22),0,(M22-N22)*IF(D$11<>"BB",$E$7,(1+$D$7)^(AK22/365)-1)) -> 3285.0489 | G23: =IF(R23=0,0,IF(M22<1,0,IF(AND(AND(((M22-N22)/R23)<G22,O22<>"V"),D$11<>"BRADESCO"),G22, (M22-N22)/R23))) -> 1031.9587 | H23: =IF(OR(G23=0,L23<1),"",IF(G23/L23>90%,"🛩",IF(G23/L23>70%,"🏎",IF(G23/L23>50%,"🚙",IF(G23/L23>30%,"🛵",IF(G23/L23>15%,"🐢","⚓️")))))) -> 🐢 | I23: =IFERROR(IF((G23+N23-S23)/L23<0,"🔙",IF((G23+N23-S23)/L23<10%,"🥾",IF((G23+N23-S23)/L23<20%,"🛴",IF((G23+N23-S23)/L23<50%,"🚴‍♂️",IF((G23+N23-S23)/L23<75%,"🚖","🚁"))))),"") -> 🥾 | J23: =G23+N23-S23 -> 363.55904 | K23: =IFERROR(J23/(L23+N23),0) -> 0.082308903 | L23: =G23+F23+A23+B23 -> 4417.0075 | M23: =IF(R23=0,0,MAX(0,M22-G23+S23-N22)) -> 392812.7 | O23: =IF(AND(N23<>"",N23<R23),"V","") | P23: =IF(N22=0,"",(L22-L23)/N22) | Q23: =IF(N23=0,"",IF(N23>M23,"🚫",IF(INT(N23/G23<1),"👍",INT(N23/G23)&"x"))) | R23: =IF(M22=0,0,IF(OR(N22=0,O22="V"),R22-1,IF(OR(D$11="BRADESCO",D$11="BB"),R22-ROUNDDOWN(N22/(M22/R22),0)-1,ROUNDUP((M22-N22+S22-(M22/R22))/(L22-F23-A23-B23),0)+1))) -> 381 | S23: =M22*$T23 -> 668.39964 | T23: =IF(M22>0,T22,0) -> 0.0017 | AA23: =-(L23+N23) -> -4417.0075 | AH23: =ROUNDUP(E23/120,0) -> 1 | AI23: =ROUNDUP(E23/36,0) -> 1 | AJ23: =ROUNDUP(E23/12,0) -> 1 | AK23: =DAY(DATE(YEAR(C23),MONTH(C23)+1,1)-1) -> 31 | AR23: =IF(INT(AW23)>0,AR22,0) -> 25 | AS23: =IF(AW23>0.1,AS22,0) -> 75 | AT23: =DATE(YEAR(AT22),MONTH(AT22)+1,1) -> 46296 | AU23: =IFERROR(AX23/BD22,0) -> 0.0026246719 | AV23: =AV22+1 -> 9 | AW23: =IF(OR(BD22<1,BE22>BD22),0,(BD22-BE22)*IF(AU$11<>"BB",$E$7,(1+$D$7)^(BY22/365)-1)) -> 3285.0489 | AX23: =IF(BI23=0,0,IF(BD22<1,0,IF(AND(AND(((BD22-BE22)/BI23)<AX22,BF22<>"V"),AU$11<>"BRADESCO"),AX22, (BD22-BE22)/BI23))) -> 1031.9587 | AY23: =IF(OR(AX23=0,BC23<1),"",IF(AX23/BC23>90%,"🛩",IF(AX23/BC23>70%,"🏎",IF(AX23/BC23>50%,"🚙",IF(AX23/BC23>30%,"🛵",IF(AX23/BC23>15%,"🐢","⚓️")))))) -> 🐢 | AZ23: =IFERROR(IF((AX23+BE23-BJ23)/BC23<0,"🔙",IF((AX23+BE23-BJ23)/BC23<10%,"🥾",IF((AX23+BE23-BJ23)/BC23<20%,"🛴",IF((AX23+BE23-BJ23)/BC23<50%,"🚴‍♂️",IF((AX23+BE23-BJ23)/BC23<75%,"🚖","🚁"))))),"") -> 🥾 | BA23: =AX23+BE23-BJ23 -> 363.55904 | BB23: =IFERROR(BA23/(BC23+BE23),0) -> 0.082308903 | BC23: =AX23+AW23+AR23+AS23 -> 4417.0075 | BD23: =IF(BI23=0,0,MAX(0,BD22-AX23+BJ23-BE22)) -> 392812.7 | BF23: =IF(AND(BE23<>"",BE23<BI23),"V","") | BG23: =IF(BE22=0,"",(BC22-BC23)/BE22) | BH23: =IF(BE23=0,"",IF(BE23>BD23,"🚫",IF(INT(BE23/AX23<1),"👍",INT(BE23/AX23)&"x"))) | BI23: =IF(BD22=0,0,IF(OR(BE22=0,BF22="V"),BI22-1,IF(OR(AU$11="BRADESCO",AU$11="BB"),BI22-ROUNDDOWN(BE22/(BD22/BI22),0)-1,ROUNDUP((BD22-BE22+BJ22-(BD22/BI22))/(BC22-AW23-AR23-AS23),0)+1))) -> 381 | BJ23: =BD22*$BK22 -> 668.39964 | BK23: =IF(BD22>0,BK22,0) -> 0.0017
A24: =IF(INT(F24)>0,A23,0) -> 25 | B24: =IF(F24>0.1,B23,0) -> 75 | C24: =DATE(YEAR(C23),MONTH(C23)+1,1) -> 46327 | D24: =IFERROR(G24/M23,0) -> 0.0026315789 | E24: =E23+1 -> 10 | F24: =IF(OR(M23<1,N23>M23),0,(M23-N23)*IF(D$11<>"BB",$E$7,(1+$D$7)^(AK23/365)-1)) -> 3282.0113 | G24: =IF(R24=0,0,IF(M23<1,0,IF(AND(AND(((M23-N23)/R24)<G23,O23<>"V"),D$11<>"BRADESCO"),G23, (M23-N23)/R24))) -> 1033.7176 | H24: =IF(OR(G24=0,L24<1),"",IF(G24/L24>90%,"🛩",IF(G24/L24>70%,"🏎",IF(G24/L24>50%,"🚙",IF(G24/L24>30%,"🛵",IF(G24/L24>15%,"🐢","⚓️")))))) -> 🐢 | I24: =IFERROR(IF((G24+N24-S24)/L24<0,"🔙",IF((G24+N24-S24)/L24<10%,"🥾",IF((G24+N24-S24)/L24<20%,"🛴",IF((G24+N24-S24)/L24<50%,"🚴‍♂️",IF((G24+N24-S24)/L24<75%,"🚖","🚁"))))),"") -> 🥾 | J24: =G24+N24-S24 -> 365.93604 | K24: =IFERROR(J24/(L24+N24),0) -> 0.082871039 | L24: =G24+F24+A24+B24 -> 4415.7289 | M24: =IF(R24=0,0,MAX(0,M23-G24+S24-N23)) -> 392446.76 | O24: =IF(AND(N24<>"",N24<R24),"V","") | P24: =IF(N23=0,"",(L23-L24)/N23) | Q24: =IF(N24=0,"",IF(N24>M24,"🚫",IF(INT(N24/G24<1),"👍",INT(N24/G24)&"x"))) | R24: =IF(M23=0,0,IF(OR(N23=0,O23="V"),R23-1,IF(OR(D$11="BRADESCO",D$11="BB"),R23-ROUNDDOWN(N23/(M23/R23),0)-1,ROUNDUP((M23-N23+S23-(M23/R23))/(L23-F24-A24-B24),0)+1))) -> 380 | S24: =M23*$T24 -> 667.78159 | T24: =IF(M23>0,T23,0) -> 0.0017 | AA24: =-(L24+N24) -> -4415.7289 | AH24: =ROUNDUP(E24/120,0) -> 1 | AI24: =ROUNDUP(E24/36,0) -> 1 | AJ24: =ROUNDUP(E24/12,0) -> 1 | AK24: =DAY(DATE(YEAR(C24),MONTH(C24)+1,1)-1) -> 30 | AR24: =IF(INT(AW24)>0,AR23,0) -> 25 | AS24: =IF(AW24>0.1,AS23,0) -> 75 | AT24: =DATE(YEAR(AT23),MONTH(AT23)+1,1) -> 46327 | AU24: =IFERROR(AX24/BD23,0) -> 0.0026315789 | AV24: =AV23+1 -> 10 | AW24: =IF(OR(BD23<1,BE23>BD23),0,(BD23-BE23)*IF(AU$11<>"BB",$E$7,(1+$D$7)^(BY23/365)-1)) -> 3282.0113 | AX24: =IF(BI24=0,0,IF(BD23<1,0,IF(AND(AND(((BD23-BE23)/BI24)<AX23,BF23<>"V"),AU$11<>"BRADESCO"),AX23, (BD23-BE23)/BI24))) -> 1033.7176 | AY24: =IF(OR(AX24=0,BC24<1),"",IF(AX24/BC24>90%,"🛩",IF(AX24/BC24>70%,"🏎",IF(AX24/BC24>50%,"🚙",IF(AX24/BC24>30%,"🛵",IF(AX24/BC24>15%,"🐢","⚓️")))))) -> 🐢 | AZ24: =IFERROR(IF((AX24+BE24-BJ24)/BC24<0,"🔙",IF((AX24+BE24-BJ24)/BC24<10%,"🥾",IF((AX24+BE24-BJ24)/BC24<20%,"🛴",IF((AX24+BE24-BJ24)/BC24<50%,"🚴‍♂️",IF((AX24+BE24-BJ24)/BC24<75%,"🚖","🚁"))))),"") -> 🥾 | BA24: =AX24+BE24-BJ24 -> 365.93604 | BB24: =IFERROR(BA24/(BC24+BE24),0) -> 0.082871039 | BC24: =AX24+AW24+AR24+AS24 -> 4415.7289 | BD24: =IF(BI24=0,0,MAX(0,BD23-AX24+BJ24-BE23)) -> 392446.76 | BF24: =IF(AND(BE24<>"",BE24<BI24),"V","") | BG24: =IF(BE23=0,"",(BC23-BC24)/BE23) | BH24: =IF(BE24=0,"",IF(BE24>BD24,"🚫",IF(INT(BE24/AX24<1),"👍",INT(BE24/AX24)&"x"))) | BI24: =IF(BD23=0,0,IF(OR(BE23=0,BF23="V"),BI23-1,IF(OR(AU$11="BRADESCO",AU$11="BB"),BI23-ROUNDDOWN(BE23/(BD23/BI23),0)-1,ROUNDUP((BD23-BE23+BJ23-(BD23/BI23))/(BC23-AW24-AR24-AS24),0)+1))) -> 380 | BJ24: =BD23*$BK23 -> 667.78159 | BK24: =IF(BD23>0,BK23,0) -> 0.0017
A25: =IF(INT(F25)>0,A24,0) -> 25 | B25: =IF(F25>0.1,B24,0) -> 75 | C25: =DATE(YEAR(C24),MONTH(C24)+1,1) -> 46357 | D25: =IFERROR(G25/M24,0) -> 0.0026385224 | E25: =E24+1 -> 11 | F25: =IF(OR(M24<1,N24>M24),0,(M24-N24)*IF(D$11<>"BB",$E$7,(1+$D$7)^(AK24/365)-1)) -> 3278.9538 | G25: =IF(R25=0,0,IF(M24<1,0,IF(AND(AND(((M24-N24)/R25)<G24,O24<>"V"),D$11<>"BRADESCO"),G24, (M24-N24)/R25))) -> 1035.4796 | H25: =IF(OR(G25=0,L25<1),"",IF(G25/L25>90%,"🛩",IF(G25/L25>70%,"🏎",IF(G25/L25>50%,"🚙",IF(G25/L25>30%,"🛵",IF(G25/L25>15%,"🐢","⚓️")))))) -> 🐢 | I25: =IFERROR(IF((G25+N25-S25)/L25<0,"🔙",IF((G25+N25-S25)/L25<10%,"🥾",IF((G25+N25-S25)/L25<20%,"🛴",IF((G25+N25-S25)/L25<50%,"🚴‍♂️",IF((G25+N25-S25)/L25<75%,"🚖","🚁"))))),"") -> 🥾 | J25: =G25+N25-S25 -> 368.32009 | K25: =IFERROR(J25/(L25+N25),0) -> 0.083435417 | L25: =G25+F25+A25+B25 -> 4414.4334 | M25: =IF(R25=0,0,MAX(0,M24-G25+S25-N24)) -> 392078.44 | O25: =IF(AND(N25<>"",N25<R25),"V","") | P25: =IF(N24=0,"",(L24-L25)/N24) | Q25: =IF(N25=0,"",IF(N25>M25,"🚫",IF(INT(N25/G25<1),"👍",INT(N25/G25)&"x"))) | R25: =IF(M24=0,0,IF(OR(N24=0,O24="V"),R24-1,IF(OR(D$11="BRADESCO",D$11="BB"),R24-ROUNDDOWN(N24/(M24/R24),0)-1,ROUNDUP((M24-N24+S24-(M24/R24))/(L24-F25-A25-B25),0)+1))) -> 379 | S25: =M24*$T25 -> 667.1595 | T25: =IF(M24>0,T24,0) -> 0.0017 | AA25: =-(L25+N25) -> -4414.4334 | AD25: ATENÇÃO: Esta planilha deve ser usada apenas para simulações | AH25: =ROUNDUP(E25/120,0) -> 1 | AI25: =ROUNDUP(E25/36,0) -> 1 | AJ25: =ROUNDUP(E25/12,0) -> 1 | AK25: =DAY(DATE(YEAR(C25),MONTH(C25)+1,1)-1) -> 31 | AR25: =IF(INT(AW25)>0,AR24,0) -> 25 | AS25: =IF(AW25>0.1,AS24,0) -> 75 | AT25: =DATE(YEAR(AT24),MONTH(AT24)+1,1) -> 46357 | AU25: =IFERROR(AX25/BD24,0) -> 0.0026385224 | AV25: =AV24+1 -> 11 | AW25: =IF(OR(BD24<1,BE24>BD24),0,(BD24-BE24)*IF(AU$11<>"BB",$E$7,(1+$D$7)^(BY24/365)-1)) -> 3278.9538 | AX25: =IF(BI25=0,0,IF(BD24<1,0,IF(AND(AND(((BD24-BE24)/BI25)<AX24,BF24<>"V"),AU$11<>"BRADESCO"),AX24, (BD24-BE24)/BI25))) -> 1035.4796 | AY25: =IF(OR(AX25=0,BC25<1),"",IF(AX25/BC25>90%,"🛩",IF(AX25/BC25>70%,"🏎",IF(AX25/BC25>50%,"🚙",IF(AX25/BC25>30%,"🛵",IF(AX25/BC25>15%,"🐢","⚓️")))))) -> 🐢 | AZ25: =IFERROR(IF((AX25+BE25-BJ25)/BC25<0,"🔙",IF((AX25+BE25-BJ25)/BC25<10%,"🥾",IF((AX25+BE25-BJ25)/BC25<20%,"🛴",IF((AX25+BE25-BJ25)/BC25<50%,"🚴‍♂️",IF((AX25+BE25-BJ25)/BC25<75%,"🚖","🚁"))))),"") -> 🥾 | BA25: =AX25+BE25-BJ25 -> 368.32009 | BB25: =IFERROR(BA25/(BC25+BE25),0) -> 0.083435417 | BC25: =AX25+AW25+AR25+AS25 -> 4414.4334 | BD25: =IF(BI25=0,0,MAX(0,BD24-AX25+BJ25-BE24)) -> 392078.44 | BF25: =IF(AND(BE25<>"",BE25<BI25),"V","") | BG25: =IF(BE24=0,"",(BC24-BC25)/BE24) | BH25: =IF(BE25=0,"",IF(BE25>BD25,"🚫",IF(INT(BE25/AX25<1),"👍",INT(BE25/AX25)&"x"))) | BI25: =IF(BD24=0,0,IF(OR(BE24=0,BF24="V"),BI24-1,IF(OR(AU$11="BRADESCO",AU$11="BB"),BI24-ROUNDDOWN(BE24/(BD24/BI24),0)-1,ROUNDUP((BD24-BE24+BJ24-(BD24/BI24))/(BC24-AW25-AR25-AS25),0)+1))) -> 379 | BJ25: =BD24*$BK24 -> 667.1595 | BK25: =IF(BD24>0,BK24,0) -> 0.0017
A26: =IF(INT(F26)>0,A25,0) -> 25 | B26: =IF(F26>0.1,B25,0) -> 75 | C26: =DATE(YEAR(C25),MONTH(C25)+1,1) -> 46388 | D26: =IFERROR(G26/M25,0) -> 0.0026455026 | E26: =E25+1 -> 12 | F26: =IF(OR(M25<1,N25>M25),0,(M25-N25)*IF(D$11<>"BB",$E$7,(1+$D$7)^(AK25/365)-1)) -> 3275.8764 | G26: =IF(R26=0,0,IF(M25<1,0,IF(AND(AND(((M25-N25)/R26)<G25,O25<>"V"),D$11<>"BRADESCO"),G25, (M25-N25)/R26))) -> 1037.2446 | H26: =IF(OR(G26=0,L26<1),"",IF(G26/L26>90%,"🛩",IF(G26/L26>70%,"🏎",IF(G26/L26>50%,"🚙",IF(G26/L26>30%,"🛵",IF(G26/L26>15%,"🐢","⚓️")))))) -> 🐢 | I26: =IFERROR(IF((G26+N26-S26)/L26<0,"🔙",IF((G26+N26-S26)/L26<10%,"🥾",IF((G26+N26-S26)/L26<20%,"🛴",IF((G26+N26-S26)/L26<50%,"🚴‍♂️",IF((G26+N26-S26)/L26<75%,"🚖","🚁"))))),"") -> 🥾 | J26: =G26+N26-S26 -> 370.71121 | K26: =IFERROR(J26/(L26+N26),0) -> 0.084002049 | L26: =G26+F26+A26+B26 -> 4413.121 | M26: =IF(R26=0,0,MAX(0,M25-G26+S26-N25)) -> 391707.73 | O26: =IF(AND(N26<>"",N26<R26),"V","") | P26: =IF(N25=0,"",(L25-L26)/N25) | Q26: =IF(N26=0,"",IF(N26>M26,"🚫",IF(INT(N26/G26<1),"👍",INT(N26/G26)&"x"))) | R26: =IF(M25=0,0,IF(OR(N25=0,O25="V"),R25-1,IF(OR(D$11="BRADESCO",D$11="BB"),R25-ROUNDDOWN(N25/(M25/R25),0)-1,ROUNDUP((M25-N25+S25-(M25/R25))/(L25-F26-A26-B26),0)+1))) -> 378 | S26: =M25*$T26 -> 666.53335 | T26: =IF(M25>0,T25,0) -> 0.0017 | AA26: =-(L26+N26) -> -4413.121 | AD26: e planejamentos futuros. | AH26: =ROUNDUP(E26/120,0) -> 1 | AI26: =ROUNDUP(E26/36,0) -> 1 | AJ26: =ROUNDUP(E26/12,0) -> 1 | AK26: =DAY(DATE(YEAR(C26),MONTH(C26)+1,1)-1) -> 31 | AR26: =IF(INT(AW26)>0,AR25,0) -> 25 | AS26: =IF(AW26>0.1,AS25,0) -> 75 | AT26: =DATE(YEAR(AT25),MONTH(AT25)+1,1) -> 46388 | AU26: =IFERROR(AX26/BD25,0) -> 0.0026455026 | AV26: =AV25+1 -> 12 | AW26: =IF(OR(BD25<1,BE25>BD25),0,(BD25-BE25)*IF(AU$11<>"BB",$E$7,(1+$D$7)^(BY25/365)-1)) -> 3275.8764 | AX26: =IF(BI26=0,0,IF(BD25<1,0,IF(AND(AND(((BD25-BE25)/BI26)<AX25,BF25<>"V"),AU$11<>"BRADESCO"),AX25, (BD25-BE25)/BI26))) -> 1037.2446 | AY26: =IF(OR(AX26=0,BC26<1),"",IF(AX26/BC26>90%,"🛩",IF(AX26/BC26>70%,"🏎",IF(AX26/BC26>50%,"🚙",IF(AX26/BC26>30%,"🛵",IF(AX26/BC26>15%,"🐢","⚓️")))))) -> 🐢 | AZ26: =IFERROR(IF((AX26+BE26-BJ26)/BC26<0,"🔙",IF((AX26+BE26-BJ26)/BC26<10%,"🥾",IF((AX26+BE26-BJ26)/BC26<20%,"🛴",IF((AX26+BE26-BJ26)/BC26<50%,"🚴‍♂️",IF((AX26+BE26-BJ26)/BC26<75%,"🚖","🚁"))))),"") -> 🥾 | BA26: =AX26+BE26-BJ26 -> 370.71121 | BB26: =IFERROR(BA26/(BC26+BE26),0) -> 0.084002049 | BC26: =AX26+AW26+AR26+AS26 -> 4413.121 | BD26: =IF(BI26=0,0,MAX(0,BD25-AX26+BJ26-BE25)) -> 391707.73 | BF26: =IF(AND(BE26<>"",BE26<BI26),"V","") | BG26: =IF(BE25=0,"",(BC25-BC26)/BE25) | BH26: =IF(BE26=0,"",IF(BE26>BD26,"🚫",IF(INT(BE26/AX26<1),"👍",INT(BE26/AX26)&"x"))) | BI26: =IF(BD25=0,0,IF(OR(BE25=0,BF25="V"),BI25-1,IF(OR(AU$11="BRADESCO",AU$11="BB"),BI25-ROUNDDOWN(BE25/(BD25/BI25),0)-1,ROUNDUP((BD25-BE25+BJ25-(BD25/BI25))/(BC25-AW26-AR26-AS26),0)+1))) -> 378 | BJ26: =BD25*$BK25 -> 666.53335 | BK26: =IF(BD25>0,BK25,0) -> 0.0017
A27: =IF(INT(F27)>0,A26,0) -> 25 | B27: =IF(F27>0.1,B26,0) -> 75 | C27: =DATE(YEAR(C26),MONTH(C26)+1,1) -> 46419 | D27: =IFERROR(G27/M26,0) -> 0.0026525199 | E27: =E26+1 -> 13 | F27: =IF(OR(M26<1,N26>M26),0,(M26-N26)*IF(D$11<>"BB",$E$7,(1+$D$7)^(AK26/365)-1)) -> 3272.7791 | G27: =IF(R27=0,0,IF(M26<1,0,IF(AND(AND(((M26-N26)/R27)<G26,O26<>"V"),D$11<>"BRADESCO"),G26, (M26-N26)/R27))) -> 1039.0126 | H27: =IF(OR(G27=0,L27<1),"",IF(G27/L27>90%,"🛩",IF(G27/L27>70%,"🏎",IF(G27/L27>50%,"🚙",IF(G27/L27>30%,"🛵",IF(G27/L27>15%,"🐢","⚓️")))))) -> 🐢 | I27: =IFERROR(IF((G27+N27-S27)/L27<0,"🔙",IF((G27+N27-S27)/L27<10%,"🥾",IF((G27+N27-S27)/L27<20%,"🛴",IF((G27+N27-S27)/L27<50%,"🚴‍♂️",IF((G27+N27-S27)/L27<75%,"🚖","🚁"))))),"") -> 🥾 | J27: =G27+N27-S27 -> 373.10941 | K27: =IFERROR(J27/(L27+N27),0) -> 0.084570949 | L27: =G27+F27+A27+B27 -> 4411.7916 | M27: =IF(R27=0,0,MAX(0,M26-G27+S27-N26)) -> 391334.62 | O27: =IF(AND(N27<>"",N27<R27),"V","") | P27: =IF(N26=0,"",(L26-L27)/N26) | Q27: =IF(N27=0,"",IF(N27>M27,"🚫",IF(INT(N27/G27<1),"👍",INT(N27/G27)&"x"))) | R27: =IF(M26=0,0,IF(OR(N26=0,O26="V"),R26-1,IF(OR(D$11="BRADESCO",D$11="BB"),R26-ROUNDDOWN(N26/(M26/R26),0)-1,ROUNDUP((M26-N26+S26-(M26/R26))/(L26-F27-A27-B27),0)+1))) -> 377 | S27: =M26*$T27 -> 665.90315 | T27: =IF(M26>0,T26,0) -> 0.0017 | AA27: =-(L27+N27) -> -4411.7916 | AD27: Confira sempre os valores no seu Documento Descritivo de Crédito. | AH27: =ROUNDUP(E27/120,0) -> 1 | AI27: =ROUNDUP(E27/36,0) -> 1 | AJ27: =ROUNDUP(E27/12,0) -> 2 | AK27: =DAY(DATE(YEAR(C27),MONTH(C27)+1,1)-1) -> 28 | AR27: =IF(INT(AW27)>0,AR26,0) -> 25 | AS27: =IF(AW27>0.1,AS26,0) -> 75 | AT27: =DATE(YEAR(AT26),MONTH(AT26)+1,1) -> 46419 | AU27: =IFERROR(AX27/BD26,0) -> 0.0026525199 | AV27: =AV26+1 -> 13 | AW27: =IF(OR(BD26<1,BE26>BD26),0,(BD26-BE26)*IF(AU$11<>"BB",$E$7,(1+$D$7)^(BY26/365)-1)) -> 3272.7791 | AX27: =IF(BI27=0,0,IF(BD26<1,0,IF(AND(AND(((BD26-BE26)/BI27)<AX26,BF26<>"V"),AU$11<>"BRADESCO"),AX26, (BD26-BE26)/BI27))) -> 1039.0126 | AY27: =IF(OR(AX27=0,BC27<1),"",IF(AX27/BC27>90%,"🛩",IF(AX27/BC27>70%,"🏎",IF(AX27/BC27>50%,"🚙",IF(AX27/BC27>30%,"🛵",IF(AX27/BC27>15%,"🐢","⚓️")))))) -> 🐢 | AZ27: =IFERROR(IF((AX27+BE27-BJ27)/BC27<0,"🔙",IF((AX27+BE27-BJ27)/BC27<10%,"🥾",IF((AX27+BE27-BJ27)/BC27<20%,"🛴",IF((AX27+BE27-BJ27)/BC27<50%,"🚴‍♂️",IF((AX27+BE27-BJ27)/BC27<75%,"🚖","🚁"))))),"") -> 🥾 | BA27: =AX27+BE27-BJ27 -> 373.10941 | BB27: =IFERROR(BA27/(BC27+BE27),0) -> 0.084570949 | BC27: =AX27+AW27+AR27+AS27 -> 4411.7916 | BD27: =IF(BI27=0,0,MAX(0,BD26-AX27+BJ27-BE26)) -> 391334.62 | BF27: =IF(AND(BE27<>"",BE27<BI27),"V","") | BG27: =IF(BE26=0,"",(BC26-BC27)/BE26) | BH27: =IF(BE27=0,"",IF(BE27>BD27,"🚫",IF(INT(BE27/AX27<1),"👍",INT(BE27/AX27)&"x"))) | BI27: =IF(BD26=0,0,IF(OR(BE26=0,BF26="V"),BI26-1,IF(OR(AU$11="BRADESCO",AU$11="BB"),BI26-ROUNDDOWN(BE26/(BD26/BI26),0)-1,ROUNDUP((BD26-BE26+BJ26-(BD26/BI26))/(BC26-AW27-AR27-AS27),0)+1))) -> 377 | BJ27: =BD26*$BK26 -> 665.90315 | BK27: =IF(BD26>0,BK26,0) -> 0.0017
A28: =IF(INT(F28)>0,A27,0) -> 25 | B28: =IF(F28>0.1,B27,0) -> 75 | C28: =DATE(YEAR(C27),MONTH(C27)+1,1) -> 46447 | D28: =IFERROR(G28/M27,0) -> 0.0026595745 | E28: =E27+1 -> 14 | F28: =IF(OR(M27<1,N27>M27),0,(M27-N27)*IF(D$11<>"BB",$E$7,(1+$D$7)^(AK27/365)-1)) -> 3269.6617 | G28: =IF(R28=0,0,IF(M27<1,0,IF(AND(AND(((M27-N27)/R28)<G27,O27<>"V"),D$11<>"BRADESCO"),G27, (M27-N27)/R28))) -> 1040.7836 | H28: =IF(OR(G28=0,L28<1),"",IF(G28/L28>90%,"🛩",IF(G28/L28>70%,"🏎",IF(G28/L28>50%,"🚙",IF(G28/L28>30%,"🛵",IF(G28/L28>15%,"🐢","⚓️")))))) -> 🐢 | I28: =IFERROR(IF((G28+N28-S28)/L28<0,"🔙",IF((G28+N28-S28)/L28<10%,"🥾",IF((G28+N28-S28)/L28<20%,"🛴",IF((G28+N28-S28)/L28<50%,"🚴‍♂️",IF((G28+N28-S28)/L28<75%,"🚖","🚁"))))),"") -> 🥾 | J28: =G28+N28-S28 -> 375.51471 | K28: =IFERROR(J28/(L28+N28),0) -> 0.085142132 | L28: =G28+F28+A28+B28 -> 4410.4453 | M28: =IF(R28=0,0,MAX(0,M27-G28+S28-N27)) -> 390959.11 | O28: =IF(AND(N28<>"",N28<R28),"V","") | P28: =IF(N27=0,"",(L27-L28)/N27) | Q28: =IF(N28=0,"",IF(N28>M28,"🚫",IF(INT(N28/G28<1),"👍",INT(N28/G28)&"x"))) | R28: =IF(M27=0,0,IF(OR(N27=0,O27="V"),R27-1,IF(OR(D$11="BRADESCO",D$11="BB"),R27-ROUNDDOWN(N27/(M27/R27),0)-1,ROUNDUP((M27-N27+S27-(M27/R27))/(L27-F28-A28-B28),0)+1))) -> 376 | S28: =M27*$T28 -> 665.26886 | T28: =IF(M27>0,T27,0) -> 0.0017 | AA28: =-(L28+N28) -> -4410.4453 | AD28: Para chegar nos valores mais próximos, adicione as | AH28: =ROUNDUP(E28/120,0) -> 1 | AI28: =ROUNDUP(E28/36,0) -> 1 | AJ28: =ROUNDUP(E28/12,0) -> 2 | AK28: =DAY(DATE(YEAR(C28),MONTH(C28)+1,1)-1) -> 31 | AR28: =IF(INT(AW28)>0,AR27,0) -> 25 | AS28: =IF(AW28>0.1,AS27,0) -> 75 | AT28: =DATE(YEAR(AT27),MONTH(AT27)+1,1) -> 46447 | AU28: =IFERROR(AX28/BD27,0) -> 0.0026595745 | AV28: =AV27+1 -> 14 | AW28: =IF(OR(BD27<1,BE27>BD27),0,(BD27-BE27)*IF(AU$11<>"BB",$E$7,(1+$D$7)^(BY27/365)-1)) -> 3269.6617 | AX28: =IF(BI28=0,0,IF(BD27<1,0,IF(AND(AND(((BD27-BE27)/BI28)<AX27,BF27<>"V"),AU$11<>"BRADESCO"),AX27, (BD27-BE27)/BI28))) -> 1040.7836 | AY28: =IF(OR(AX28=0,BC28<1),"",IF(AX28/BC28>90%,"🛩",IF(AX28/BC28>70%,"🏎",IF(AX28/BC28>50%,"🚙",IF(AX28/BC28>30%,"🛵",IF(AX28/BC28>15%,"🐢","⚓️")))))) -> 🐢 | AZ28: =IFERROR(IF((AX28+BE28-BJ28)/BC28<0,"🔙",IF((AX28+BE28-BJ28)/BC28<10%,"🥾",IF((AX28+BE28-BJ28)/BC28<20%,"🛴",IF((AX28+BE28-BJ28)/BC28<50%,"🚴‍♂️",IF((AX28+BE28-BJ28)/BC28<75%,"🚖","🚁"))))),"") -> 🥾 | BA28: =AX28+BE28-BJ28 -> 375.51471 | BB28: =IFERROR(BA28/(BC28+BE28),0) -> 0.085142132 | BC28: =AX28+AW28+AR28+AS28 -> 4410.4453 | BD28: =IF(BI28=0,0,MAX(0,BD27-AX28+BJ28-BE27)) -> 390959.11 | BF28: =IF(AND(BE28<>"",BE28<BI28),"V","") | BG28: =IF(BE27=0,"",(BC27-BC28)/BE27) | BH28: =IF(BE28=0,"",IF(BE28>BD28,"🚫",IF(INT(BE28/AX28<1),"👍",INT(BE28/AX28)&"x"))) | BI28: =IF(BD27=0,0,IF(OR(BE27=0,BF27="V"),BI27-1,IF(OR(AU$11="BRADESCO",AU$11="BB"),BI27-ROUNDDOWN(BE27/(BD27/BI27),0)-1,ROUNDUP((BD27-BE27+BJ27-(BD27/BI27))/(BC27-AW28-AR28-AS28),0)+1))) -> 376 | BJ28: =BD27*$BK27 -> 665.26886 | BK28: =IF(BD27>0,BK27,0) -> 0.0017
A29: =IF(INT(F29)>0,A28,0) -> 25 | B29: =IF(F29>0.1,B28,0) -> 75 | C29: =DATE(YEAR(C28),MONTH(C28)+1,1) -> 46478 | D29: =IFERROR(G29/M28,0) -> 0.0026666667 | E29: =E28+1 -> 15 | F29: =IF(OR(M28<1,N28>M28),0,(M28-N28)*IF(D$11<>"BB",$E$7,(1+$D$7)^(AK28/365)-1)) -> 3266.5242 | G29: =IF(R29=0,0,IF(M28<1,0,IF(AND(AND(((M28-N28)/R29)<G28,O28<>"V"),D$11<>"BRADESCO"),G28, (M28-N28)/R29))) -> 1042.5576 | H29: =IF(OR(G29=0,L29<1),"",IF(G29/L29>90%,"🛩",IF(G29/L29>70%,"🏎",IF(G29/L29>50%,"🚙",IF(G29/L29>30%,"🛵",IF(G29/L29>15%,"🐢","⚓️")))))) -> 🐢 | I29: =IFERROR(IF((G29+N29-S29)/L29<0,"🔙",IF((G29+N29-S29)/L29<10%,"🥾",IF((G29+N29-S29)/L29<20%,"🛴",IF((G29+N29-S29)/L29<50%,"🚴‍♂️",IF((G29+N29-S29)/L29<75%,"🚖","🚁"))))),"") -> 🥾 | J29: =G29+N29-S29 -> 377.92714 | K29: =IFERROR(J29/(L29+N29),0) -> 0.08571561 | L29: =G29+F29+A29+B29 -> 4409.0818 | M29: =IF(R29=0,0,MAX(0,M28-G29+S29-N28)) -> 390581.18 | O29: =IF(AND(N29<>"",N29<R29),"V","") | P29: =IF(N28=0,"",(L28-L29)/N28) | Q29: =IF(N29=0,"",IF(N29>M29,"🚫",IF(INT(N29/G29<1),"👍",INT(N29/G29)&"x"))) | R29: =IF(M28=0,0,IF(OR(N28=0,O28="V"),R28-1,IF(OR(D$11="BRADESCO",D$11="BB"),R28-ROUNDDOWN(N28/(M28/R28),0)-1,ROUNDUP((M28-N28+S28-(M28/R28))/(L28-F29-A29-B29),0)+1))) -> 375 | S29: =M28*$T29 -> 664.63048 | T29: =IF(M28>0,T28,0) -> 0.0017 | AA29: =-(L29+N29) -> -4409.0818 | AD29: correções monetárias e o seguro a cada mês. | AH29: =ROUNDUP(E29/120,0) -> 1 | AI29: =ROUNDUP(E29/36,0) -> 1 | AJ29: =ROUNDUP(E29/12,0) -> 2 | AK29: =DAY(DATE(YEAR(C29),MONTH(C29)+1,1)-1) -> 30 | AR29: =IF(INT(AW29)>0,AR28,0) -> 25 | AS29: =IF(AW29>0.1,AS28,0) -> 75 | AT29: =DATE(YEAR(AT28),MONTH(AT28)+1,1) -> 46478 | AU29: =IFERROR(AX29/BD28,0) -> 0.0026666667 | AV29: =AV28+1 -> 15 | AW29: =IF(OR(BD28<1,BE28>BD28),0,(BD28-BE28)*IF(AU$11<>"BB",$E$7,(1+$D$7)^(BY28/365)-1)) -> 3266.5242 | AX29: =IF(BI29=0,0,IF(BD28<1,0,IF(AND(AND(((BD28-BE28)/BI29)<AX28,BF28<>"V"),AU$11<>"BRADESCO"),AX28, (BD28-BE28)/BI29))) -> 1042.5576 | AY29: =IF(OR(AX29=0,BC29<1),"",IF(AX29/BC29>90%,"🛩",IF(AX29/BC29>70%,"🏎",IF(AX29/BC29>50%,"🚙",IF(AX29/BC29>30%,"🛵",IF(AX29/BC29>15%,"🐢","⚓️")))))) -> 🐢 | AZ29: =IFERROR(IF((AX29+BE29-BJ29)/BC29<0,"🔙",IF((AX29+BE29-BJ29)/BC29<10%,"🥾",IF((AX29+BE29-BJ29)/BC29<20%,"🛴",IF((AX29+BE29-BJ29)/BC29<50%,"🚴‍♂️",IF((AX29+BE29-BJ29)/BC29<75%,"🚖","🚁"))))),"") -> 🥾 | BA29: =AX29+BE29-BJ29 -> 377.92714 | BB29: =IFERROR(BA29/(BC29+BE29),0) -> 0.08571561 | BC29: =AX29+AW29+AR29+AS29 -> 4409.0818 | BD29: =IF(BI29=0,0,MAX(0,BD28-AX29+BJ29-BE28)) -> 390581.18 | BF29: =IF(AND(BE29<>"",BE29<BI29),"V","") | BG29: =IF(BE28=0,"",(BC28-BC29)/BE28) | BH29: =IF(BE29=0,"",IF(BE29>BD29,"🚫",IF(INT(BE29/AX29<1),"👍",INT(BE29/AX29)&"x"))) | BI29: =IF(BD28=0,0,IF(OR(BE28=0,BF28="V"),BI28-1,IF(OR(AU$11="BRADESCO",AU$11="BB"),BI28-ROUNDDOWN(BE28/(BD28/BI28),0)-1,ROUNDUP((BD28-BE28+BJ28-(BD28/BI28))/(BC28-AW29-AR29-AS29),0)+1))) -> 375 | BJ29: =BD28*$BK28 -> 664.63048 | BK29: =IF(BD28>0,BK28,0) -> 0.0017
A30: =IF(INT(F30)>0,A29,0) -> 25 | B30: =IF(F30>0.1,B29,0) -> 75 | C30: =DATE(YEAR(C29),MONTH(C29)+1,1) -> 46508 | D30: =IFERROR(G30/M29,0) -> 0.0026737968 | E30: =E29+1 -> 16 | F30: =IF(OR(M29<1,N29>M29),0,(M29-N29)*IF(D$11<>"BB",$E$7,(1+$D$7)^(AK29/365)-1)) -> 3263.3666 | G30: =IF(R30=0,0,IF(M29<1,0,IF(AND(AND(((M29-N29)/R30)<G29,O29<>"V"),D$11<>"BRADESCO"),G29, (M29-N29)/R30))) -> 1044.3347 | H30: =IF(OR(G30=0,L30<1),"",IF(G30/L30>90%,"🛩",IF(G30/L30>70%,"🏎",IF(G30/L30>50%,"🚙",IF(G30/L30>30%,"🛵",IF(G30/L30>15%,"🐢","⚓️")))))) -> 🐢 | I30: =IFERROR(IF((G30+N30-S30)/L30<0,"🔙",IF((G30+N30-S30)/L30<10%,"🥾",IF((G30+N30-S30)/L30<20%,"🛴",IF((G30+N30-S30)/L30<50%,"🚴‍♂️",IF((G30+N30-S30)/L30<75%,"🚖","🚁"))))),"") -> 🥾 | J30: =G30+N30-S30 -> 380.3467 | K30: =IFERROR(J30/(L30+N30),0) -> 0.086291397 | L30: =G30+F30+A30+B30 -> 4407.7013 | M30: =IF(R30=0,0,MAX(0,M29-G30+S30-N29)) -> 390200.83 | O30: =IF(AND(N30<>"",N30<R30),"V","") | P30: =IF(N29=0,"",(L29-L30)/N29) | Q30: =IF(N30=0,"",IF(N30>M30,"🚫",IF(INT(N30/G30<1),"👍",INT(N30/G30)&"x"))) | R30: =IF(M29=0,0,IF(OR(N29=0,O29="V"),R29-1,IF(OR(D$11="BRADESCO",D$11="BB"),R29-ROUNDDOWN(N29/(M29/R29),0)-1,ROUNDUP((M29-N29+S29-(M29/R29))/(L29-F30-A30-B30),0)+1))) -> 374 | S30: =M29*$T30 -> 663.98801 | T30: =IF(M29>0,T29,0) -> 0.0017 | AA30: =-(L30+N30) -> -4407.7013 | AD30: https://www.habitacaodigital.caixa.gov.br/ | AH30: =ROUNDUP(E30/120,0) -> 1 | AI30: =ROUNDUP(E30/36,0) -> 1 | AJ30: =ROUNDUP(E30/12,0) -> 2 | AK30: =DAY(DATE(YEAR(C30),MONTH(C30)+1,1)-1) -> 31 | AR30: =IF(INT(AW30)>0,AR29,0) -> 25 | AS30: =IF(AW30>0.1,AS29,0) -> 75 | AT30: =DATE(YEAR(AT29),MONTH(AT29)+1,1) -> 46508 | AU30: =IFERROR(AX30/BD29,0) -> 0.0026737968 | AV30: =AV29+1 -> 16 | AW30: =IF(OR(BD29<1,BE29>BD29),0,(BD29-BE29)*IF(AU$11<>"BB",$E$7,(1+$D$7)^(BY29/365)-1)) -> 3263.3666 | AX30: =IF(BI30=0,0,IF(BD29<1,0,IF(AND(AND(((BD29-BE29)/BI30)<AX29,BF29<>"V"),AU$11<>"BRADESCO"),AX29, (BD29-BE29)/BI30))) -> 1044.3347 | AY30: =IF(OR(AX30=0,BC30<1),"",IF(AX30/BC30>90%,"🛩",IF(AX30/BC30>70%,"🏎",IF(AX30/BC30>50%,"🚙",IF(AX30/BC30>30%,"🛵",IF(AX30/BC30>15%,"🐢","⚓️")))))) -> 🐢 | AZ30: =IFERROR(IF((AX30+BE30-BJ30)/BC30<0,"🔙",IF((AX30+BE30-BJ30)/BC30<10%,"🥾",IF((AX30+BE30-BJ30)/BC30<20%,"🛴",IF((AX30+BE30-BJ30)/BC30<50%,"🚴‍♂️",IF((AX30+BE30-BJ30)/BC30<75%,"🚖","🚁"))))),"") -> 🥾 | BA30: =AX30+BE30-BJ30 -> 380.3467 | BB30: =IFERROR(BA30/(BC30+BE30),0) -> 0.086291397 | BC30: =AX30+AW30+AR30+AS30 -> 4407.7013 | BD30: =IF(BI30=0,0,MAX(0,BD29-AX30+BJ30-BE29)) -> 390200.83 | BF30: =IF(AND(BE30<>"",BE30<BI30),"V","") | BG30: =IF(BE29=0,"",(BC29-BC30)/BE29) | BH30: =IF(BE30=0,"",IF(BE30>BD30,"🚫",IF(INT(BE30/AX30<1),"👍",INT(BE30/AX30)&"x"))) | BI30: =IF(BD29=0,0,IF(OR(BE29=0,BF29="V"),BI29-1,IF(OR(AU$11="BRADESCO",AU$11="BB"),BI29-ROUNDDOWN(BE29/(BD29/BI29),0)-1,ROUNDUP((BD29-BE29+BJ29-(BD29/BI29))/(BC29-AW30-AR30-AS30),0)+1))) -> 374 | BJ30: =BD29*$BK29 -> 663.98801 | BK30: =IF(BD29>0,BK29,0) -> 0.0017
A31: =IF(INT(F31)>0,A30,0) -> 25 | B31: =IF(F31>0.1,B30,0) -> 75 | C31: =DATE(YEAR(C30),MONTH(C30)+1,1) -> 46539 | D31: =IFERROR(G31/M30,0) -> 0.0026809651 | E31: =E30+1 -> 17 | F31: =IF(OR(M30<1,N30>M30),0,(M30-N30)*IF(D$11<>"BB",$E$7,(1+$D$7)^(AK30/365)-1)) -> 3260.1887 | G31: =IF(R31=0,0,IF(M30<1,0,IF(AND(AND(((M30-N30)/R31)<G30,O30<>"V"),D$11<>"BRADESCO"),G30, (M30-N30)/R31))) -> 1046.1148 | H31: =IF(OR(G31=0,L31<1),"",IF(G31/L31>90%,"🛩",IF(G31/L31>70%,"🏎",IF(G31/L31>50%,"🚙",IF(G31/L31>30%,"🛵",IF(G31/L31>15%,"🐢","⚓️")))))) -> 🐢 | I31: =IFERROR(IF((G31+N31-S31)/L31<0,"🔙",IF((G31+N31-S31)/L31<10%,"🥾",IF((G31+N31-S31)/L31<20%,"🛴",IF((G31+N31-S31)/L31<50%,"🚴‍♂️",IF((G31+N31-S31)/L31<75%,"🚖","🚁"))))),"") -> 🥾 | J31: =G31+N31-S31 -> 382.77342 | K31: =IFERROR(J31/(L31+N31),0) -> 0.086869507 | L31: =G31+F31+A31+B31 -> 4406.3036 | M31: =IF(R31=0,0,MAX(0,M30-G31+S31-N30)) -> 389818.06 | O31: =IF(AND(N31<>"",N31<R31),"V","") | P31: =IF(N30=0,"",(L30-L31)/N30) | Q31: =IF(N31=0,"",IF(N31>M31,"🚫",IF(INT(N31/G31<1),"👍",INT(N31/G31)&"x"))) | R31: =IF(M30=0,0,IF(OR(N30=0,O30="V"),R30-1,IF(OR(D$11="BRADESCO",D$11="BB"),R30-ROUNDDOWN(N30/(M30/R30),0)-1,ROUNDUP((M30-N30+S30-(M30/R30))/(L30-F31-A31-B31),0)+1))) -> 373 | S31: =M30*$T31 -> 663.34142 | T31: =IF(M30>0,T30,0) -> 0.0017 | AA31: =-(L31+N31) -> -4406.3036 | AD31: Documento Descritivo de Crédito | AH31: =ROUNDUP(E31/120,0) -> 1 | AI31: =ROUNDUP(E31/36,0) -> 1 | AJ31: =ROUNDUP(E31/12,0) -> 2 | AK31: =DAY(DATE(YEAR(C31),MONTH(C31)+1,1)-1) -> 30 | AR31: =IF(INT(AW31)>0,AR30,0) -> 25 | AS31: =IF(AW31>0.1,AS30,0) -> 75 | AT31: =DATE(YEAR(AT30),MONTH(AT30)+1,1) -> 46539 | AU31: =IFERROR(AX31/BD30,0) -> 0.0026809651 | AV31: =AV30+1 -> 17 | AW31: =IF(OR(BD30<1,BE30>BD30),0,(BD30-BE30)*IF(AU$11<>"BB",$E$7,(1+$D$7)^(BY30/365)-1)) -> 3260.1887 | AX31: =IF(BI31=0,0,IF(BD30<1,0,IF(AND(AND(((BD30-BE30)/BI31)<AX30,BF30<>"V"),AU$11<>"BRADESCO"),AX30, (BD30-BE30)/BI31))) -> 1046.1148 | AY31: =IF(OR(AX31=0,BC31<1),"",IF(AX31/BC31>90%,"🛩",IF(AX31/BC31>70%,"🏎",IF(AX31/BC31>50%,"🚙",IF(AX31/BC31>30%,"🛵",IF(AX31/BC31>15%,"🐢","⚓️")))))) -> 🐢 | AZ31: =IFERROR(IF((AX31+BE31-BJ31)/BC31<0,"🔙",IF((AX31+BE31-BJ31)/BC31<10%,"🥾",IF((AX31+BE31-BJ31)/BC31<20%,"🛴",IF((AX31+BE31-BJ31)/BC31<50%,"🚴‍♂️",IF((AX31+BE31-BJ31)/BC31<75%,"🚖","🚁"))))),"") -> 🥾 | BA31: =AX31+BE31-BJ31 -> 382.77342 | BB31: =IFERROR(BA31/(BC31+BE31),0) -> 0.086869507 | BC31: =AX31+AW31+AR31+AS31 -> 4406.3036 | BD31: =IF(BI31=0,0,MAX(0,BD30-AX31+BJ31-BE30)) -> 389818.06 | BF31: =IF(AND(BE31<>"",BE31<BI31),"V","") | BG31: =IF(BE30=0,"",(BC30-BC31)/BE30) | BH31: =IF(BE31=0,"",IF(BE31>BD31,"🚫",IF(INT(BE31/AX31<1),"👍",INT(BE31/AX31)&"x"))) | BI31: =IF(BD30=0,0,IF(OR(BE30=0,BF30="V"),BI30-1,IF(OR(AU$11="BRADESCO",AU$11="BB"),BI30-ROUNDDOWN(BE30/(BD30/BI30),0)-1,ROUNDUP((BD30-BE30+BJ30-(BD30/BI30))/(BC30-AW31-AR31-AS31),0)+1))) -> 373 | BJ31: =BD30*$BK30 -> 663.34142 | BK31: =IF(BD30>0,BK30,0) -> 0.0017
A32: =IF(INT(F32)>0,A31,0) -> 25 | B32: =IF(F32>0.1,B31,0) -> 75 | C32: =DATE(YEAR(C31),MONTH(C31)+1,1) -> 46569 | D32: =IFERROR(G32/M31,0) -> 0.002688172 | E32: =E31+1 -> 18 | F32: =IF(OR(M31<1,N31>M31),0,(M31-N31)*IF(D$11<>"BB",$E$7,(1+$D$7)^(AK31/365)-1)) -> 3256.9906 | G32: =IF(R32=0,0,IF(M31<1,0,IF(AND(AND(((M31-N31)/R32)<G31,O31<>"V"),D$11<>"BRADESCO"),G31, (M31-N31)/R32))) -> 1047.898 | H32: =IF(OR(G32=0,L32<1),"",IF(G32/L32>90%,"🛩",IF(G32/L32>70%,"🏎",IF(G32/L32>50%,"🚙",IF(G32/L32>30%,"🛵",IF(G32/L32>15%,"🐢","⚓️")))))) -> 🐢 | I32: =IFERROR(IF((G32+N32-S32)/L32<0,"🔙",IF((G32+N32-S32)/L32<10%,"🥾",IF((G32+N32-S32)/L32<20%,"🛴",IF((G32+N32-S32)/L32<50%,"🚴‍♂️",IF((G32+N32-S32)/L32<75%,"🚖","🚁"))))),"") -> 🥾 | J32: =G32+N32-S32 -> 385.20731 | K32: =IFERROR(J32/(L32+N32),0) -> 0.087449955 | L32: =G32+F32+A32+B32 -> 4404.8886 | M32: =IF(R32=0,0,MAX(0,M31-G32+S32-N31)) -> 389432.85 | O32: =IF(AND(N32<>"",N32<R32),"V","") | P32: =IF(N31=0,"",(L31-L32)/N31) | Q32: =IF(N32=0,"",IF(N32>M32,"🚫",IF(INT(N32/G32<1),"👍",INT(N32/G32)&"x"))) | R32: =IF(M31=0,0,IF(OR(N31=0,O31="V"),R31-1,IF(OR(D$11="BRADESCO",D$11="BB"),R31-ROUNDDOWN(N31/(M31/R31),0)-1,ROUNDUP((M31-N31+S31-(M31/R31))/(L31-F32-A32-B32),0)+1))) -> 372 | S32: =M31*$T32 -> 662.6907 | T32: =IF(M31>0,T31,0) -> 0.0017 | AA32: =-(L32+N32) -> -4404.8886 | AH32: =ROUNDUP(E32/120,0) -> 1 | AI32: =ROUNDUP(E32/36,0) -> 1 | AJ32: =ROUNDUP(E32/12,0) -> 2 | AK32: =DAY(DATE(YEAR(C32),MONTH(C32)+1,1)-1) -> 31 | AR32: =IF(INT(AW32)>0,AR31,0) -> 25 | AS32: =IF(AW32>0.1,AS31,0) -> 75 | AT32: =DATE(YEAR(AT31),MONTH(AT31)+1,1) -> 46569 | AU32: =IFERROR(AX32/BD31,0) -> 0.002688172 | AV32: =AV31+1 -> 18 | AW32: =IF(OR(BD31<1,BE31>BD31),0,(BD31-BE31)*IF(AU$11<>"BB",$E$7,(1+$D$7)^(BY31/365)-1)) -> 3256.9906 | AX32: =IF(BI32=0,0,IF(BD31<1,0,IF(AND(AND(((BD31-BE31)/BI32)<AX31,BF31<>"V"),AU$11<>"BRADESCO"),AX31, (BD31-BE31)/BI32))) -> 1047.898 | AY32: =IF(OR(AX32=0,BC32<1),"",IF(AX32/BC32>90%,"🛩",IF(AX32/BC32>70%,"🏎",IF(AX32/BC32>50%,"🚙",IF(AX32/BC32>30%,"🛵",IF(AX32/BC32>15%,"🐢","⚓️")))))) -> 🐢 | AZ32: =IFERROR(IF((AX32+BE32-BJ32)/BC32<0,"🔙",IF((AX32+BE32-BJ32)/BC32<10%,"🥾",IF((AX32+BE32-BJ32)/BC32<20%,"🛴",IF((AX32+BE32-BJ32)/BC32<50%,"🚴‍♂️",IF((AX32+BE32-BJ32)/BC32<75%,"🚖","🚁"))))),"") -> 🥾 | BA32: =AX32+BE32-BJ32 -> 385.20731 | BB32: =IFERROR(BA32/(BC32+BE32),0) -> 0.087449955 | BC32: =AX32+AW32+AR32+AS32 -> 4404.8886 | BD32: =IF(BI32=0,0,MAX(0,BD31-AX32+BJ32-BE31)) -> 389432.85 | BF32: =IF(AND(BE32<>"",BE32<BI32),"V","") | BG32: =IF(BE31=0,"",(BC31-BC32)/BE31) | BH32: =IF(BE32=0,"",IF(BE32>BD32,"🚫",IF(INT(BE32/AX32<1),"👍",INT(BE32/AX32)&"x"))) | BI32: =IF(BD31=0,0,IF(OR(BE31=0,BF31="V"),BI31-1,IF(OR(AU$11="BRADESCO",AU$11="BB"),BI31-ROUNDDOWN(BE31/(BD31/BI31),0)-1,ROUNDUP((BD31-BE31+BJ31-(BD31/BI31))/(BC31-AW32-AR32-AS32),0)+1))) -> 372 | BJ32: =BD31*$BK31 -> 662.6907 | BK32: =IF(BD31>0,BK31,0) -> 0.0017
A33: =IF(INT(F33)>0,A32,0) -> 25 | B33: =IF(F33>0.1,B32,0) -> 75 | C33: =DATE(YEAR(C32),MONTH(C32)+1,1) -> 46600 | D33: =IFERROR(G33/M32,0) -> 0.0026954178 | E33: =E32+1 -> 19 | F33: =IF(OR(M32<1,N32>M32),0,(M32-N32)*IF(D$11<>"BB",$E$7,(1+$D$7)^(AK32/365)-1)) -> 3253.7721 | G33: =IF(R33=0,0,IF(M32<1,0,IF(AND(AND(((M32-N32)/R33)<G32,O32<>"V"),D$11<>"BRADESCO"),G32, (M32-N32)/R33))) -> 1049.6842 | H33: =IF(OR(G33=0,L33<1),"",IF(G33/L33>90%,"🛩",IF(G33/L33>70%,"🏎",IF(G33/L33>50%,"🚙",IF(G33/L33>30%,"🛵",IF(G33/L33>15%,"🐢","⚓️")))))) -> 🐢 | I33: =IFERROR(IF((G33+N33-S33)/L33<0,"🔙",IF((G33+N33-S33)/L33<10%,"🥾",IF((G33+N33-S33)/L33<20%,"🛴",IF((G33+N33-S33)/L33<50%,"🚴‍♂️",IF((G33+N33-S33)/L33<75%,"🚖","🚁"))))),"") -> 🥾 | J33: =G33+N33-S33 -> 387.64839 | K33: =IFERROR(J33/(L33+N33),0) -> 0.088032754 | L33: =G33+F33+A33+B33 -> 4403.4564 | M33: =IF(R33=0,0,MAX(0,M32-G33+S33-N32)) -> 389045.21 | O33: =IF(AND(N33<>"",N33<R33),"V","") | P33: =IF(N32=0,"",(L32-L33)/N32) | Q33: =IF(N33=0,"",IF(N33>M33,"🚫",IF(INT(N33/G33<1),"👍",INT(N33/G33)&"x"))) | R33: =IF(M32=0,0,IF(OR(N32=0,O32="V"),R32-1,IF(OR(D$11="BRADESCO",D$11="BB"),R32-ROUNDDOWN(N32/(M32/R32),0)-1,ROUNDUP((M32-N32+S32-(M32/R32))/(L32-F33-A33-B33),0)+1))) -> 371 | S33: =M32*$T33 -> 662.03585 | T33: =IF(M32>0,T32,0) -> 0.0017 | AA33: =-(L33+N33) -> -4403.4564 | AD33: Autor: Alessandro Rodolpho Gonçalves da Silva | AH33: =ROUNDUP(E33/120,0) -> 1 | AI33: =ROUNDUP(E33/36,0) -> 1 | AJ33: =ROUNDUP(E33/12,0) -> 2 | AK33: =DAY(DATE(YEAR(C33),MONTH(C33)+1,1)-1) -> 31 | AR33: =IF(INT(AW33)>0,AR32,0) -> 25 | AS33: =IF(AW33>0.1,AS32,0) -> 75 | AT33: =DATE(YEAR(AT32),MONTH(AT32)+1,1) -> 46600 | AU33: =IFERROR(AX33/BD32,0) -> 0.0026954178 | AV33: =AV32+1 -> 19 | AW33: =IF(OR(BD32<1,BE32>BD32),0,(BD32-BE32)*IF(AU$11<>"BB",$E$7,(1+$D$7)^(BY32/365)-1)) -> 3253.7721 | AX33: =IF(BI33=0,0,IF(BD32<1,0,IF(AND(AND(((BD32-BE32)/BI33)<AX32,BF32<>"V"),AU$11<>"BRADESCO"),AX32, (BD32-BE32)/BI33))) -> 1049.6842 | AY33: =IF(OR(AX33=0,BC33<1),"",IF(AX33/BC33>90%,"🛩",IF(AX33/BC33>70%,"🏎",IF(AX33/BC33>50%,"🚙",IF(AX33/BC33>30%,"🛵",IF(AX33/BC33>15%,"🐢","⚓️")))))) -> 🐢 | AZ33: =IFERROR(IF((AX33+BE33-BJ33)/BC33<0,"🔙",IF((AX33+BE33-BJ33)/BC33<10%,"🥾",IF((AX33+BE33-BJ33)/BC33<20%,"🛴",IF((AX33+BE33-BJ33)/BC33<50%,"🚴‍♂️",IF((AX33+BE33-BJ33)/BC33<75%,"🚖","🚁"))))),"") -> 🥾 | BA33: =AX33+BE33-BJ33 -> 387.64839 | BB33: =IFERROR(BA33/(BC33+BE33),0) -> 0.088032754 | BC33: =AX33+AW33+AR33+AS33 -> 4403.4564 | BD33: =IF(BI33=0,0,MAX(0,BD32-AX33+BJ33-BE32)) -> 389045.21 | BF33: =IF(AND(BE33<>"",BE33<BI33),"V","") | BG33: =IF(BE32=0,"",(BC32-BC33)/BE32) | BH33: =IF(BE33=0,"",IF(BE33>BD33,"🚫",IF(INT(BE33/AX33<1),"👍",INT(BE33/AX33)&"x"))) | BI33: =IF(BD32=0,0,IF(OR(BE32=0,BF32="V"),BI32-1,IF(OR(AU$11="BRADESCO",AU$11="BB"),BI32-ROUNDDOWN(BE32/(BD32/BI32),0)-1,ROUNDUP((BD32-BE32+BJ32-(BD32/BI32))/(BC32-AW33-AR33-AS33),0)+1))) -> 371 | BJ33: =BD32*$BK32 -> 662.03585 | BK33: =IF(BD32>0,BK32,0) -> 0.0017
